Workbook

Sheet RELATORIO_DIA
A1: Relatório diário
A2: Data: | B2: =TODAY()
A4: Total de registos | B4: =COUNTA(macs_ips!$A$2:$A$403)
A5: A dever | B5: =COUNTIF(macs_ips!$E$2:$E$403,"A dever")
A6: Em dia | B6: =COUNTIF(macs_ips!$E$2:$E$403,"Em dia")
A7: Sem contacto | B7: =COUNTIF(macs_ips!$E$2:$E$403,"Sem contacto")
A8: Sem resposta | B8: =COUNTIF(macs_ips!$E$2:$E$403,"Sem resposta")
A9: Expirados (data exp < hoje) | B9: =COUNTIFS(macs_ips!$D$2:$D$403,"<"&TODAY(),macs_ips!$D$2:$D$403,"<>")
A10: Próximas ações (<= hoje) | B10: =COUNTIFS(macs_ips!$F$2:$F$403,"<="&TODAY(),macs_ips!$F$2:$F$403,"<>")
A11: Próximas ações (próx. 7 dias) | B11: =COUNTIFS(macs_ips!$F$2:$F$403,">="&TODAY(),macs_ips!$F$2:$F$403,"<="&TODAY()+7)

Sheet macs_ips
A1: MAC | B1: Ips | C1: Contactos | D1: data exp | E1: Situação | F1: data da proxima ação | G1: observação | H1: RowID
A2: 18:e8:29:34:9c:c0 | B2: 10.12.252.168 | C2: 862052606 | D2: 45911 | E2: sem resposta | H2: 1
A3: fc:ec:da:52:18:4f | B3: 10.12.252.50 | C3: 843443902 | D3: 45907 | E3: sem resposta | H3: 2
A4: f4:92:bf:f0:a2:c3 | B4: 10.12.252.92 | C4: 845100103 | D4: 45757 | E4: sem resposta | H4: 3
A5: f4:e2:c6:82:5e:d5 | B5: 10.12.254.112 | C5: 843688770 | D5: 45987 | E5: em espera | G5: no ultimo contacto o cliente disse que estava na teledata | H5: 4
A6: fc:ec:da:58:e0:fc | B6: 10.12.254.163 | C6: 865019473 | D6: 45946 | E6: continua | G6: proxima semana | H6: 5
A7: 18:e8:29:3e:d8:f8 | B7: 10.12.254.188 | C7: 876077745 | D7: 45981 | E7: continua | G7: proxima semana | H7: 6
A8: f4:e2:c6:92:c8:ba | B8: 10.12.254.216 | C8: 847894281 | D8: 45995 | E8: continua | G8: proxima semana | H8: 7
A9: 18:e8:29:34:9f:46 | B9: 10.12.254.223 | C9: 843460491 | D9: 46009 | E9: continua | G9: proxima semana | H9: 8
A10: 78:8a:20:e6:18:f7 | B10: 10.12.254.228 | C10: 867178868 | D10: 45904 | E10: continua | G10: proxima semana | H10: 9
A11: f0:9f:c2:88:eb:0f | B11: 10.12.254.44 | C11: 877124635 | D11: 45989 | E11: em espera | G11: Remoção do Equipamennto | H11: 10
A12: 60:22:32:d8:71:99 | B12: 10.12.254.56 | C12: 866152424 | D12: 46012 | E12: cancelou | F12: 46063 | G12: Remoção do Equipamennto | H12: 11
A13: 68:d7:9a:aa:b9:6a | B13: 10.12.254.78 | C13: 842145742 | D13: 45959 | E13: cancelou | G13: Equipamento atribuido a outro cliente | H13: 12
A14: 18:e8:29:da:12:fa | B14: 10.12.254.86 | C14: 841828585 | D14: 46014 | E14: continua | G14: por informar | H14: 13
A15: 68:d7:9a:9e:d8:12 | B15: 10.16.254.139 | C15: 842638818 | D15: 45603 | E15: sem resposta | H15: 14
A16: 24:5a:4c:d0:d4:cf | B16: 10.16.254.141 | C16: 844778290 | D16: 46021 | E16: sem resposta | H16: 15
A17: f4:e2:c6:92:c5:d9 | B17: 10.16.254.3 | C17: 843999330 | D17: 45831 | E17: em espera | H17: 16
A18: 60:22:32:d8:72:60 | B18: 10.16.254.78 | C18: 847028726 | D18: 46008 | E18: continua | F18: 46058 | G18: pago | H18: 17
A19: 68:d7:9a:aa:b8:d8 | B19: 10.22.100.13 | C19: 842811466 | D19: 45911 | E19: sem resposta | H19: 18
A20: 60:22:32:d4:6d:a5 | B20: 10.22.100.21 | C20: 848192044 | D20: 45982 | E20: sem resposta | H20: 19
A21: f4:e2:c6:92:92:1b | B21: 10.22.100.27 | C21: 847502455 | D21: 45870 | E21: continua | F21: 46058 | G21: pago | H21: 20
A22: fc:ec:da:6e:0a:ea | B22: 10.22.102.12 | C22: 847101009 | D22: 46087 | E22: continua | G22: pago | H22: 21
A23: e0:63:da:48:6e:ee | B23: 10.22.102.140 | C23: 823184720 | D23: 46016 | E23: sem resposta | H23: 22
A24: 70:a7:41:18:82:61 | B24: 10.22.102.143 | C24: 841444459 | D24: 45928 | E24: continua | G24: por informar | H24: 23
A25: 04:18:d6:e8:94:7a | B25: 10.22.102.157 | C25: sem contacto valido | D25: 45934 | E25: …........... | G25: a aguardar por novas informações | H25: 24
A26: 04:18:d6:54:d2:69 | B26: 10.22.102.176 | C26: 874902520 | D26: 45931 | E26: sem resposta | H26: 25
A27: e0:63:da:4c:26:97 | B27: 10.22.102.178 | C27: 864586127 | D27: 45970 | E27: sem resposta | H27: 26
A28: 44:d9:e7:2a:41:e6 | B28: 10.22.102.183 | C28: 824717650 | D28: 45995 | E28: continua | F28: 46064 | G28: Pagamento | H28: 27
A29: 60:22:32:ce:7f:8a | B29: 10.22.102.199 | C29: 870049329 | D29: 45868 | E29: sem resposta | H29: 28
A30: 60:22:32:ce:85:71 | B30: 10.22.102.200 | C30: 845890085 | D30: 45469 | E30: sem resposta | H30: 29
A31: 60:22:32:ce:87:0e | B31: 10.22.102.217 | C31: 824985320 | D31: 45935 | E31: em espera | H31: 30
A32: 60:22:32:d8:5e:ce | B32: 10.22.102.226 | C32: 842398560 | D32: 45953 | E32: continua | G32: por informar | H32: 31
A33: f4:e2:c6:92:f0:7d | B33: 10.22.102.252 | C33: 863434230 | D33: 45801 | E33: continua | F33: 46058 | G33: pago | H33: 32
A34: f4:e2:c6:92:90:7c | B34: 10.22.102.36 | C34: 863452684 | D34: 45892 | E34: cancelou | F34: 46058.521 | G34: Remoção do Equipamennto | H34: 33
A35: 04:18:d6:96:84:16 | B35: 10.22.102.53 | C35: 843155720 | D35: 45993 | E35: sem resposta | H35: 34
A36: fc:ec:da:26:c7:48 | B36: 10.22.102.60 | C36: 847778607 | D36: 45759 | E36: em espera | H36: 35
A37: 9c:05:d6:8c:5c:94 | B37: 10.22.102.99 | C37: 847720619 | D37: 45869 | E37: sem resposta | H37: 36
A38: 28:70:4e:ba:e6:e8 | B38: 10.22.103.107 | C38: 861581111 | D38: 46015 | E38: continua | G38: proxima semana | H38: 37
A39: 44:d9:e7:0a:fd:89 | B39: 10.22.103.4 | C39: 877001985 | D39: 45473 | E39: sem resposta | H39: 38
A40: f4:e2:c6:88:21:55 | B40: 10.22.103.43 | C40: 870236950 | D40: 46003 | E40: sem resposta | H40: 39
...

Sheet LISTAS
A1: Situação (lista)
A2: A dever
A3: Em dia
A4: Sem contacto
A5: Sem resposta
A6: Em negociação
A7: Em espera
A8: Cancelado
A9: Cortado
A10: Continua

Sheet A_DEVER
A1: CLIENTES — A dever | J1: A dever
A2: MAC | B2: Ips | C2: Contactos | D2: data exp | E2: Situação | F2: data da proxima ação | G2: observação
A3: =IFERROR(INDEX('macs_ips'!$A$2:$A$403,AGGREGATE(15,6,(ROW('macs_ips'!$A$2:$A$403)-ROW(INDEX('macs_ips'!$A$2:$A$403,1,1))+1)/('macs_ips'!$E$2:$E$403=$J$1),ROW(A1))),"") | B3: =IFERROR(INDEX('macs_ips'!$B$2:$B$403,AGGREGATE(15,6,(ROW('macs_ips'!$A$2:$A$403)-ROW(INDEX('macs_ips'!$A$2:$A$403,1,1))+1)/('macs_ips'!$E$2:$E$403=$J$1),ROW(A1))),"") | C3: =IFERROR(INDEX('macs_ips'!$C$2:$C$403,AGGREGATE(15,6,(ROW('macs_ips'!$A$2:$A$403)-ROW(INDEX('macs_ips'!$A$2:$A$403,1,1))+1)/('macs_ips'!$E$2:$E$403=$J$1),ROW(A1))),"") | D3: =IFERROR(INDEX('macs_ips'!$D$2:$D$403,AGGREGATE(15,6,(ROW('macs_ips'!$A$2:$A$403)-ROW(INDEX('macs_ips'!$A$2:$A$403,1,1))+1)/('macs_ips'!$E$2:$E$403=$J$1),ROW(A1))),"") | E3: =IFERROR(INDEX('macs_ips'!$E$2:$E$403,AGGREGATE(15,6,(ROW('macs_ips'!$A$2:$A$403)-ROW(INDEX('macs_ips'!$A$2:$A$403,1,1))+1)/('macs_ips'!$E$2:$E$403=$J$1),ROW(A1))),"") | F3: =IFERROR(INDEX('macs_ips'!$F$2:$F$403,AGGREGATE(15,6,(ROW('macs_ips'!$A$2:$A$403)-ROW(INDEX('macs_ips'!$A$2:$A$403,1,1))+1)/('macs_ips'!$E$2:$E$403=$J$1),ROW(A1))),"") | G3: =IFERROR(INDEX('macs_ips'!$G$2:$G$403,AGGREGATE(15,6,(ROW('macs_ips'!$A$2:$A$403)-ROW(INDEX('macs_ips'!$A$2:$A$403,1,1))+1)/('macs_ips'!$E$2:$E$403=$J$1),ROW(A1))),"")
A4: =IFERROR(INDEX('macs_ips'!$A$2:$A$403,AGGREGATE(15,6,(ROW('macs_ips'!$A$2:$A$403)-ROW(INDEX('macs_ips'!$A$2:$A$403,1,1))+1)/('macs_ips'!$E$2:$E$403=$J$1),ROW(A2))),"") | B4: =IFERROR(INDEX('macs_ips'!$B$2:$B$403,AGGREGATE(15,6,(ROW('macs_ips'!$A$2:$A$403)-ROW(INDEX('macs_ips'!$A$2:$A$403,1,1))+1)/('macs_ips'!$E$2:$E$403=$J$1),ROW(A2))),"") | C4: =IFERROR(INDEX('macs_ips'!$C$2:$C$403,AGGREGATE(15,6,(ROW('macs_ips'!$A$2:$A$403)-ROW(INDEX('macs_ips'!$A$2:$A$403,1,1))+1)/('macs_ips'!$E$2:$E$403=$J$1),ROW(A2))),"") | D4: =IFERROR(INDEX('macs_ips'!$D$2:$D$403,AGGREGATE(15,6,(ROW('macs_ips'!$A$2:$A$403)-ROW(INDEX('macs_ips'!$A$2:$A$403,1,1))+1)/('macs_ips'!$E$2:$E$403=$J$1),ROW(A2))),"") | E4: =IFERROR(INDEX('macs_ips'!$E$2:$E$403,AGGREGATE(15,6,(ROW('macs_ips'!$A$2:$A$403)-ROW(INDEX('macs_ips'!$A$2:$A$403,1,1))+1)/('macs_ips'!$E$2:$E$403=$J$1),ROW(A2))),"") | F4: =IFERROR(INDEX('macs_ips'!$F$2:$F$403,AGGREGATE(15,6,(ROW('macs_ips'!$A$2:$A$403)-ROW(INDEX('macs_ips'!$A$2:$A$403,1,1))+1)/('macs_ips'!$E$2:$E$403=$J$1),ROW(A2))),"") | G4: =IFERROR(INDEX('macs_ips'!$G$2:$G$403,AGGREGATE(15,6,(ROW('macs_ips'!$A$2:$A$403)-ROW(INDEX('macs_ips'!$A$2:$A$403,1,1))+1)/('macs_ips'!$E$2:$E$403=$J$1),ROW(A2))),"")
A5: =IFERROR(INDEX('macs_ips'!$A$2:$A$403,AGGREGATE(15,6,(ROW('macs_ips'!$A$2:$A$403)-ROW(INDEX('macs_ips'!$A$2:$A$403,1,1))+1)/('macs_ips'!$E$2:$E$403=$J$1),ROW(A3))),"") | B5: =IFERROR(INDEX('macs_ips'!$B$2:$B$403,AGGREGATE(15,6,(ROW('macs_ips'!$A$2:$A$403)-ROW(INDEX('macs_ips'!$A$2:$A$403,1,1))+1)/('macs_ips'!$E$2:$E$403=$J$1),ROW(A3))),"") | C5: =IFERROR(INDEX('macs_ips'!$C$2:$C$403,AGGREGATE(15,6,(ROW('macs_ips'!$A$2:$A$403)-ROW(INDEX('macs_ips'!$A$2:$A$403,1,1))+1)/('macs_ips'!$E$2:$E$403=$J$1),ROW(A3))),"") | D5: =IFERROR(INDEX('macs_ips'!$D$2:$D$403,AGGREGATE(15,6,(ROW('macs_ips'!$A$2:$A$403)-ROW(INDEX('macs_ips'!$A$2:$A$403,1,1))+1)/('macs_ips'!$E$2:$E$403=$J$1),ROW(A3))),"") | E5: =IFERROR(INDEX('macs_ips'!$E$2:$E$403,AGGREGATE(15,6,(ROW('macs_ips'!$A$2:$A$403)-ROW(INDEX('macs_ips'!$A$2:$A$403,1,1))+1)/('macs_ips'!$E$2:$E$403=$J$1),ROW(A3))),"") | F5: =IFERROR(INDEX('macs_ips'!$F$2:$F$403,AGGREGATE(15,6,(ROW('macs_ips'!$A$2:$A$403)-ROW(INDEX('macs_ips'!$A$2:$A$403,1,1))+1)/('macs_ips'!$E$2:$E$403=$J$1),ROW(A3))),"") | G5: =IFERROR(INDEX('macs_ips'!$G$2:$G$403,AGGREGATE(15,6,(ROW('macs_ips'!$A$2:$A$403)-ROW(INDEX('macs_ips'!$A$2:$A$403,1,1))+1)/('macs_ips'!$E$2:$E$403=$J$1),ROW(A3))),"")
A6: =IFERROR(INDEX('macs_ips'!$A$2:$A$403,AGGREGATE(15,6,(ROW('macs_ips'!$A$2:$A$403)-ROW(INDEX('macs_ips'!$A$2:$A$403,1,1))+1)/('macs_ips'!$E$2:$E$403=$J$1),ROW(A4))),"") | B6: =IFERROR(INDEX('macs_ips'!$B$2:$B$403,AGGREGATE(15,6,(ROW('macs_ips'!$A$2:$A$403)-ROW(INDEX('macs_ips'!$A$2:$A$403,1,1))+1)/('macs_ips'!$E$2:$E$403=$J$1),ROW(A4))),"") | C6: =IFERROR(INDEX('macs_ips'!$C$2:$C$403,AGGREGATE(15,6,(ROW('macs_ips'!$A$2:$A$403)-ROW(INDEX('macs_ips'!$A$2:$A$403,1,1))+1)/('macs_ips'!$E$2:$E$403=$J$1),ROW(A4))),"") | D6: =IFERROR(INDEX('macs_ips'!$D$2:$D$403,AGGREGATE(15,6,(ROW('macs_ips'!$A$2:$A$403)-ROW(INDEX('macs_ips'!$A$2:$A$403,1,1))+1)/('macs_ips'!$E$2:$E$403=$J$1),ROW(A4))),"") | E6: =IFERROR(INDEX('macs_ips'!$E$2:$E$403,AGGREGATE(15,6,(ROW('macs_ips'!$A$2:$A$403)-ROW(INDEX('macs_ips'!$A$2:$A$403,1,1))+1)/('macs_ips'!$E$2:$E$403=$J$1),ROW(A4))),"") | F6: =IFERROR(INDEX('macs_ips'!$F$2:$F$403,AGGREGATE(15,6,(ROW('macs_ips'!$A$2:$A$403)-ROW(INDEX('macs_ips'!$A$2:$A$403,1,1))+1)/('macs_ips'!$E$2:$E$403=$J$1),ROW(A4))),"") | G6: =IFERROR(INDEX('macs_ips'!$G$2:$G$403,AGGREGATE(15,6,(ROW('macs_ips'!$A$2:$A$403)-ROW(INDEX('macs_ips'!$A$2:$A$403,1,1))+1)/('macs_ips'!$E$2:$E$403=$J$1),ROW(A4))),"")
A7: =IFERROR(INDEX('macs_ips'!$A$2:$A$403,AGGREGATE(15,6,(ROW('macs_ips'!$A$2:$A$403)-ROW(INDEX('macs_ips'!$A$2:$A$403,1,1))+1)/('macs_ips'!$E$2:$E$403=$J$1),ROW(A5))),"") | B7: =IFERROR(INDEX('macs_ips'!$B$2:$B$403,AGGREGATE(15,6,(ROW('macs_ips'!$A$2:$A$403)-ROW(INDEX('macs_ips'!$A$2:$A$403,1,1))+1)/('macs_ips'!$E$2:$E$403=$J$1),ROW(A5))),"") | C7: =IFERROR(INDEX('macs_ips'!$C$2:$C$403,AGGREGATE(15,6,(ROW('macs_ips'!$A$2:$A$403)-ROW(INDEX('macs_ips'!$A$2:$A$403,1,1))+1)/('macs_ips'!$E$2:$E$403=$J$1),ROW(A5))),"") | D7: =IFERROR(INDEX('macs_ips'!$D$2:$D$403,AGGREGATE(15,6,(ROW('macs_ips'!$A$2:$A$403)-ROW(INDEX('macs_ips'!$A$2:$A$403,1,1))+1)/('macs_ips'!$E$2:$E$403=$J$1),ROW(A5))),"") | E7: =IFERROR(INDEX('macs_ips'!$E$2:$E$403,AGGREGATE(15,6,(ROW('macs_ips'!$A$2:$A$403)-ROW(INDEX('macs_ips'!$A$2:$A$403,1,1))+1)/('macs_ips'!$E$2:$E$403=$J$1),ROW(A5))),"") | F7: =IFERROR(INDEX('macs_ips'!$F$2:$F$403,AGGREGATE(15,6,(ROW('macs_ips'!$A$2:$A$403)-ROW(INDEX('macs_ips'!$A$2:$A$403,1,1))+1)/('macs_ips'!$E$2:$E$403=$J$1),ROW(A5))),"") | G7: =IFERROR(INDEX('macs_ips'!$G$2:$G$403,AGGREGATE(15,6,(ROW('macs_ips'!$A$2:$A$403)-ROW(INDEX('macs_ips'!$A$2:$A$403,1,1))+1)/('macs_ips'!$E$2:$E$403=$J$1),ROW(A5))),"")
A8: =IFERROR(INDEX('macs_ips'!$A$2:$A$403,AGGREGATE(15,6,(ROW('macs_ips'!$A$2:$A$403)-ROW(INDEX('macs_ips'!$A$2:$A$403,1,1))+1)/('macs_ips'!$E$2:$E$403=$J$1),ROW(A6))),"") | B8: =IFERROR(INDEX('macs_ips'!$B$2:$B$403,AGGREGATE(15,6,(ROW('macs_ips'!$A$2:$A$403)-ROW(INDEX('macs_ips'!$A$2:$A$403,1,1))+1)/('macs_ips'!$E$2:$E$403=$J$1),ROW(A6))),"") | C8: =IFERROR(INDEX('macs_ips'!$C$2:$C$403,AGGREGATE(15,6,(ROW('macs_ips'!$A$2:$A$403)-ROW(INDEX('macs_ips'!$A$2:$A$403,1,1))+1)/('macs_ips'!$E$2:$E$403=$J$1),ROW(A6))),"") | D8: =IFERROR(INDEX('macs_ips'!$D$2:$D$403,AGGREGATE(15,6,(ROW('macs_ips'!$A$2:$A$403)-ROW(INDEX('macs_ips'!$A$2:$A$403,1,1))+1)/('macs_ips'!$E$2:$E$403=$J$1),ROW(A6))),"") | E8: =IFERROR(INDEX('macs_ips'!$E$2:$E$403,AGGREGATE(15,6,(ROW('macs_ips'!$A$2:$A$403)-ROW(INDEX('macs_ips'!$A$2:$A$403,1,1))+1)/('macs_ips'!$E$2:$E$403=$J$1),ROW(A6))),"") | F8: =IFERROR(INDEX('macs_ips'!$F$2:$F$403,AGGREGATE(15,6,(ROW('macs_ips'!$A$2:$A$403)-ROW(INDEX('macs_ips'!$A$2:$A$403,1,1))+1)/('macs_ips'!$E$2:$E$403=$J$1),ROW(A6))),"") | G8: =IFERROR(INDEX('macs_ips'!$G$2:$G$403,AGGREGATE(15,6,(ROW('macs_ips'!$A$2:$A$403)-ROW(INDEX('macs_ips'!$A$2:$A$403,1,1))+1)/('macs_ips'!$E$2:$E$403=$J$1),ROW(A6))),"")
A9: =IFERROR(INDEX('macs_ips'!$A$2:$A$403,AGGREGATE(15,6,(ROW('macs_ips'!$A$2:$A$403)-ROW(INDEX('macs_ips'!$A$2:$A$403,1,1))+1)/('macs_ips'!$E$2:$E$403=$J$1),ROW(A7))),"") | B9: =IFERROR(INDEX('macs_ips'!$B$2:$B$403,AGGREGATE(15,6,(ROW('macs_ips'!$A$2:$A$403)-ROW(INDEX('macs_ips'!$A$2:$A$403,1,1))+1)/('macs_ips'!$E$2:$E$403=$J$1),ROW(A7))),"") | C9: =IFERROR(INDEX('macs_ips'!$C$2:$C$403,AGGREGATE(15,6,(ROW('macs_ips'!$A$2:$A$403)-ROW(INDEX('macs_ips'!$A$2:$A$403,1,1))+1)/('macs_ips'!$E$2:$E$403=$J$1),ROW(A7))),"") | D9: =IFERROR(INDEX('macs_ips'!$D$2:$D$403,AGGREGATE(15,6,(ROW('macs_ips'!$A$2:$A$403)-ROW(INDEX('macs_ips'!$A$2:$A$403,1,1))+1)/('macs_ips'!$E$2:$E$403=$J$1),ROW(A7))),"") | E9: =IFERROR(INDEX('macs_ips'!$E$2:$E$403,AGGREGATE(15,6,(ROW('macs_ips'!$A$2:$A$403)-ROW(INDEX('macs_ips'!$A$2:$A$403,1,1))+1)/('macs_ips'!$E$2:$E$403=$J$1),ROW(A7))),"") | F9: =IFERROR(INDEX('macs_ips'!$F$2:$F$403,AGGREGATE(15,6,(ROW('macs_ips'!$A$2:$A$403)-ROW(INDEX('macs_ips'!$A$2:$A$403,1,1))+1)/('macs_ips'!$E$2:$E$403=$J$1),ROW(A7))),"") | G9: =IFERROR(INDEX('macs_ips'!$G$2:$G$403,AGGREGATE(15,6,(ROW('macs_ips'!$A$2:$A$403)-ROW(INDEX('macs_ips'!$A$2:$A$403,1,1))+1)/('macs_ips'!$E$2:$E$403=$J$1),ROW(A7))),"")
A10: =IFERROR(INDEX('macs_ips'!$A$2:$A$403,AGGREGATE(15,6,(ROW('macs_ips'!$A$2:$A$403)-ROW(INDEX('macs_ips'!$A$2:$A$403,1,1))+1)/('macs_ips'!$E$2:$E$403=$J$1),ROW(A8))),"") | B10: =IFERROR(INDEX('macs_ips'!$B$2:$B$403,AGGREGATE(15,6,(ROW('macs_ips'!$A$2:$A$403)-ROW(INDEX('macs_ips'!$A$2:$A$403,1,1))+1)/('macs_ips'!$E$2:$E$403=$J$1),ROW(A8))),"") | C10: =IFERROR(INDEX('macs_ips'!$C$2:$C$403,AGGREGATE(15,6,(ROW('macs_ips'!$A$2:$A$403)-ROW(INDEX('macs_ips'!$A$2:$A$403,1,1))+1)/('macs_ips'!$E$2:$E$403=$J$1),ROW(A8))),"") | D10: =IFERROR(INDEX('macs_ips'!$D$2:$D$403,AGGREGATE(15,6,(ROW('macs_ips'!$A$2:$A$403)-ROW(INDEX('macs_ips'!$A$2:$A$403,1,1))+1)/('macs_ips'!$E$2:$E$403=$J$1),ROW(A8))),"") | E10: =IFERROR(INDEX('macs_ips'!$E$2:$E$403,AGGREGATE(15,6,(ROW('macs_ips'!$A$2:$A$403)-ROW(INDEX('macs_ips'!$A$2:$A$403,1,1))+1)/('macs_ips'!$E$2:$E$403=$J$1),ROW(A8))),"") | F10: =IFERROR(INDEX('macs_ips'!$F$2:$F$403,AGGREGATE(15,6,(ROW('macs_ips'!$A$2:$A$403)-ROW(INDEX('macs_ips'!$A$2:$A$403,1,1))+1)/('macs_ips'!$E$2:$E$403=$J$1),ROW(A8))),"") | G10: =IFERROR(INDEX('macs_ips'!$G$2:$G$403,AGGREGATE(15,6,(ROW('macs_ips'!$A$2:$A$403)-ROW(INDEX('macs_ips'!$A$2:$A$403,1,1))+1)/('macs_ips'!$E$2:$E$403=$J$1),ROW(A8))),"")
A11: =IFERROR(INDEX('macs_ips'!$A$2:$A$403,AGGREGATE(15,6,(ROW('macs_ips'!$A$2:$A$403)-ROW(INDEX('macs_ips'!$A$2:$A$403,1,1))+1)/('macs_ips'!$E$2:$E$403=$J$1),ROW(A9))),"") | B11: =IFERROR(INDEX('macs_ips'!$B$2:$B$403,AGGREGATE(15,6,(ROW('macs_ips'!$A$2:$A$403)-ROW(INDEX('macs_ips'!$A$2:$A$403,1,1))+1)/('macs_ips'!$E$2:$E$403=$J$1),ROW(A9))),"") | C11: =IFERROR(INDEX('macs_ips'!$C$2:$C$403,AGGREGATE(15,6,(ROW('macs_ips'!$A$2:$A$403)-ROW(INDEX('macs_ips'!$A$2:$A$403,1,1))+1)/('macs_ips'!$E$2:$E$403=$J$1),ROW(A9))),"") | D11: =IFERROR(INDEX('macs_ips'!$D$2:$D$403,AGGREGATE(15,6,(ROW('macs_ips'!$A$2:$A$403)-ROW(INDEX('macs_ips'!$A$2:$A$403,1,1))+1)/('macs_ips'!$E$2:$E$403=$J$1),ROW(A9))),"") | E11: =IFERROR(INDEX('macs_ips'!$E$2:$E$403,AGGREGATE(15,6,(ROW('macs_ips'!$A$2:$A$403)-ROW(INDEX('macs_ips'!$A$2:$A$403,1,1))+1)/('macs_ips'!$E$2:$E$403=$J$1),ROW(A9))),"") | F11: =IFERROR(INDEX('macs_ips'!$F$2:$F$403,AGGREGATE(15,6,(ROW('macs_ips'!$A$2:$A$403)-ROW(INDEX('macs_ips'!$A$2:$A$403,1,1))+1)/('macs_ips'!$E$2:$E$403=$J$1),ROW(A9))),"") | G11: =IFERROR(INDEX('macs_ips'!$G$2:$G$403,AGGREGATE(15,6,(ROW('macs_ips'!$A$2:$A$403)-ROW(INDEX('macs_ips'!$A$2:$A$403,1,1))+1)/('macs_ips'!$E$2:$E$403=$J$1),ROW(A9))),"")
A12: =IFERROR(INDEX('macs_ips'!$A$2:$A$403,AGGREGATE(15,6,(ROW('macs_ips'!$A$2:$A$403)-ROW(INDEX('macs_ips'!$A$2:$A$403,1,1))+1)/('macs_ips'!$E$2:$E$403=$J$1),ROW(A10))),"") | B12: =IFERROR(INDEX('macs_ips'!$B$2:$B$403,AGGREGATE(15,6,(ROW('macs_ips'!$A$2:$A$403)-ROW(INDEX('macs_ips'!$A$2:$A$403,1,1))+1)/('macs_ips'!$E$2:$E$403=$J$1),ROW(A10))),"") | C12: =IFERROR(INDEX('macs_ips'!$C$2:$C$403,AGGREGATE(15,6,(ROW('macs_ips'!$A$2:$A$403)-ROW(INDEX('macs_ips'!$A$2:$A$403,1,1))+1)/('macs_ips'!$E$2:$E$403=$J$1),ROW(A10))),"") | D12: =IFERROR(INDEX('macs_ips'!$D$2:$D$403,AGGREGATE(15,6,(ROW('macs_ips'!$A$2:$A$403)-ROW(INDEX('macs_ips'!$A$2:$A$403,1,1))+1)/('macs_ips'!$E$2:$E$403=$J$1),ROW(A10))),"") | E12: =IFERROR(INDEX('macs_ips'!$E$2:$E$403,AGGREGATE(15,6,(ROW('macs_ips'!$A$2:$A$403)-ROW(INDEX('macs_ips'!$A$2:$A$403,1,1))+1)/('macs_ips'!$E$2:$E$403=$J$1),ROW(A10))),"") | F12: =IFERROR(INDEX('macs_ips'!$F$2:$F$403,AGGREGATE(15,6,(ROW('macs_ips'!$A$2:$A$403)-ROW(INDEX('macs_ips'!$A$2:$A$403,1,1))+1)/('macs_ips'!$E$2:$E$403=$J$1),ROW(A10))),"") | G12: =IFERROR(INDEX('macs_ips'!$G$2:$G$403,AGGREGATE(15,6,(ROW('macs_ips'!$A$2:$A$403)-ROW(INDEX('macs_ips'!$A$2:$A$403,1,1))+1)/('macs_ips'!$E$2:$E$403=$J$1),ROW(A10))),"")
A13: =IFERROR(INDEX('macs_ips'!$A$2:$A$403,AGGREGATE(15,6,(ROW('macs_ips'!$A$2:$A$403)-ROW(INDEX('macs_ips'!$A$2:$A$403,1,1))+1)/('macs_ips'!$E$2:$E$403=$J$1),ROW(A11))),"") | B13: =IFERROR(INDEX('macs_ips'!$B$2:$B$403,AGGREGATE(15,6,(ROW('macs_ips'!$A$2:$A$403)-ROW(INDEX('macs_ips'!$A$2:$A$403,1,1))+1)/('macs_ips'!$E$2:$E$403=$J$1),ROW(A11))),"") | C13: =IFERROR(INDEX('macs_ips'!$C$2:$C$403,AGGREGATE(15,6,(ROW('macs_ips'!$A$2:$A$403)-ROW(INDEX('macs_ips'!$A$2:$A$403,1,1))+1)/('macs_ips'!$E$2:$E$403=$J$1),ROW(A11))),"") | D13: =IFERROR(INDEX('macs_ips'!$D$2:$D$403,AGGREGATE(15,6,(ROW('macs_ips'!$A$2:$A$403)-ROW(INDEX('macs_ips'!$A$2:$A$403,1,1))+1)/('macs_ips'!$E$2:$E$403=$J$1),ROW(A11))),"") | E13: =IFERROR(INDEX('macs_ips'!$E$2:$E$403,AGGREGATE(15,6,(ROW('macs_ips'!$A$2:$A$403)-ROW(INDEX('macs_ips'!$A$2:$A$403,1,1))+1)/('macs_ips'!$E$2:$E$403=$J$1),ROW(A11))),"") | F13: =IFERROR(INDEX('macs_ips'!$F$2:$F$403,AGGREGATE(15,6,(ROW('macs_ips'!$A$2:$A$403)-ROW(INDEX('macs_ips'!$A$2:$A$403,1,1))+1)/('macs_ips'!$E$2:$E$403=$J$1),ROW(A11))),"") | G13: =IFERROR(INDEX('macs_ips'!$G$2:$G$403,AGGREGATE(15,6,(ROW('macs_ips'!$A$2:$A$403)-ROW(INDEX('macs_ips'!$A$2:$A$403,1,1))+1)/('macs_ips'!$E$2:$E$403=$J$1),ROW(A11))),"")
A14: =IFERROR(INDEX('macs_ips'!$A$2:$A$403,AGGREGATE(15,6,(ROW('macs_ips'!$A$2:$A$403)-ROW(INDEX('macs_ips'!$A$2:$A$403,1,1))+1)/('macs_ips'!$E$2:$E$403=$J$1),ROW(A12))),"") | B14: =IFERROR(INDEX('macs_ips'!$B$2:$B$403,AGGREGATE(15,6,(ROW('macs_ips'!$A$2:$A$403)-ROW(INDEX('macs_ips'!$A$2:$A$403,1,1))+1)/('macs_ips'!$E$2:$E$403=$J$1),ROW(A12))),"") | C14: =IFERROR(INDEX('macs_ips'!$C$2:$C$403,AGGREGATE(15,6,(ROW('macs_ips'!$A$2:$A$403)-ROW(INDEX('macs_ips'!$A$2:$A$403,1,1))+1)/('macs_ips'!$E$2:$E$403=$J$1),ROW(A12))),"") | D14: =IFERROR(INDEX('macs_ips'!$D$2:$D$403,AGGREGATE(15,6,(ROW('macs_ips'!$A$2:$A$403)-ROW(INDEX('macs_ips'!$A$2:$A$403,1,1))+1)/('macs_ips'!$E$2:$E$403=$J$1),ROW(A12))),"") | E14: =IFERROR(INDEX('macs_ips'!$E$2:$E$403,AGGREGATE(15,6,(ROW('macs_ips'!$A$2:$A$403)-ROW(INDEX('macs_ips'!$A$2:$A$403,1,1))+1)/('macs_ips'!$E$2:$E$403=$J$1),ROW(A12))),"") | F14: =IFERROR(INDEX('macs_ips'!$F$2:$F$403,AGGREGATE(15,6,(ROW('macs_ips'!$A$2:$A$403)-ROW(INDEX('macs_ips'!$A$2:$A$403,1,1))+1)/('macs_ips'!$E$2:$E$403=$J$1),ROW(A12))),"") | G14: =IFERROR(INDEX('macs_ips'!$G$2:$G$403,AGGREGATE(15,6,(ROW('macs_ips'!$A$2:$A$403)-ROW(INDEX('macs_ips'!$A$2:$A$403,1,1))+1)/('macs_ips'!$E$2:$E$403=$J$1),ROW(A12))),"")
... A452: =IFERROR(INDEX('macs_ips'!$A$2:$A$403,AGGREGATE(15,6,(ROW('macs_ips'!$A$2:$A$403)-ROW(INDEX('macs_ips'!$A$2:$A$403,1,1))+1)/('macs_ips'!$E$2:$E$403=$J$1),ROW(A450))),"") | B452: =IFERROR(INDEX('macs_ips'!$B$2:$B$403,AGGREGATE(15,6,(ROW('macs_ips'!$A$2:$A$403)-ROW(INDEX('macs_ips'!$A$2:$A$403,1,1))+1)/('macs_ips'!$E$2:$E$403=$J$1),ROW(A450))),"") | C452: =IFERROR(INDEX('macs_ips'!$C$2:$C$403,AGGREGATE(15,6,(ROW('macs_ips'!$A$2:$A$403)-ROW(INDEX('macs_ips'!$A$2:$A$403,1,1))+1)/('macs_ips'!$E$2:$E$403=$J$1),ROW(A450))),"") | D452: =IFERROR(INDEX('macs_ips'!$D$2:$D$403,AGGREGATE(15,6,(ROW('macs_ips'!$A$2:$A$403)-ROW(INDEX('macs_ips'!$A$2:$A$403,1,1))+1)/('macs_ips'!$E$2:$E$403=$J$1),ROW(A450))),"") | E452: =IFERROR(INDEX('macs_ips'!$E$2:$E$403,AGGREGATE(15,6,(ROW('macs_ips'!$A$2:$A$403)-ROW(INDEX('macs_ips'!$A$2:$A$403,1,1))+1)/('macs_ips'!$E$2:$E$403=$J$1),ROW(A450))),"") | F452: =IFERROR(INDEX('macs_ips'!$F$2:$F$403,AGGREGATE(15,6,(ROW('macs_ips'!$A$2:$A$403)-ROW(INDEX('macs_ips'!$A$2:$A$403,1,1))+1)/('macs_ips'!$E$2:$E$403=$J$1),ROW(A450))),"") | G452: =IFERROR(INDEX('macs_ips'!$G$2:$G$403,AGGREGATE(15,6,(ROW('macs_ips'!$A$2:$A$403)-ROW(INDEX('macs_ips'!$A$2:$A$403,1,1))+1)/('macs_ips'!$E$2:$E$403=$J$1),ROW(A450))),"")

Sheet EM_DIA
A1: CLIENTES — Em dia | J1: Em dia
A2: MAC | B2: Ips | C2: Contactos | D2: data exp | E2: Situação | F2: data da proxima ação | G2: observação
A3: =IFERROR(INDEX('macs_ips'!$A$2:$A$403,AGGREGATE(15,6,(ROW('macs_ips'!$A$2:$A$403)-ROW(INDEX('macs_ips'!$A$2:$A$403,1,1))+1)/('macs_ips'!$E$2:$E$403=$J$1),ROW(A1))),"") | B3: =IFERROR(INDEX('macs_ips'!$B$2:$B$403,AGGREGATE(15,6,(ROW('macs_ips'!$A$2:$A$403)-ROW(INDEX('macs_ips'!$A$2:$A$403,1,1))+1)/('macs_ips'!$E$2:$E$403=$J$1),ROW(A1))),"") | C3: =IFERROR(INDEX('macs_ips'!$C$2:$C$403,AGGREGATE(15,6,(ROW('macs_ips'!$A$2:$A$403)-ROW(INDEX('macs_ips'!$A$2:$A$403,1,1))+1)/('macs_ips'!$E$2:$E$403=$J$1),ROW(A1))),"") | D3: =IFERROR(INDEX('macs_ips'!$D$2:$D$403,AGGREGATE(15,6,(ROW('macs_ips'!$A$2:$A$403)-ROW(INDEX('macs_ips'!$A$2:$A$403,1,1))+1)/('macs_ips'!$E$2:$E$403=$J$1),ROW(A1))),"") | E3: =IFERROR(INDEX('macs_ips'!$E$2:$E$403,AGGREGATE(15,6,(ROW('macs_ips'!$A$2:$A$403)-ROW(INDEX('macs_ips'!$A$2:$A$403,1,1))+1)/('macs_ips'!$E$2:$E$403=$J$1),ROW(A1))),"") | F3: =IFERROR(INDEX('macs_ips'!$F$2:$F$403,AGGREGATE(15,6,(ROW('macs_ips'!$A$2:$A$403)-ROW(INDEX('macs_ips'!$A$2:$A$403,1,1))+1)/('macs_ips'!$E$2:$E$403=$J$1),ROW(A1))),"") | G3: =IFERROR(INDEX('macs_ips'!$G$2:$G$403,AGGREGATE(15,6,(ROW('macs_ips'!$A$2:$A$403)-ROW(INDEX('macs_ips'!$A$2:$A$403,1,1))+1)/('macs_ips'!$E$2:$E$403=$J$1),ROW(A1))),"")
A4: =IFERROR(INDEX('macs_ips'!$A$2:$A$403,AGGREGATE(15,6,(ROW('macs_ips'!$A$2:$A$403)-ROW(INDEX('macs_ips'!$A$2:$A$403,1,1))+1)/('macs_ips'!$E$2:$E$403=$J$1),ROW(A2))),"") | B4: =IFERROR(INDEX('macs_ips'!$B$2:$B$403,AGGREGATE(15,6,(ROW('macs_ips'!$A$2:$A$403)-ROW(INDEX('macs_ips'!$A$2:$A$403,1,1))+1)/('macs_ips'!$E$2:$E$403=$J$1),ROW(A2))),"") | C4: =IFERROR(INDEX('macs_ips'!$C$2:$C$403,AGGREGATE(15,6,(ROW('macs_ips'!$A$2:$A$403)-ROW(INDEX('macs_ips'!$A$2:$A$403,1,1))+1)/('macs_ips'!$E$2:$E$403=$J$1),ROW(A2))),"") | D4: =IFERROR(INDEX('macs_ips'!$D$2:$D$403,AGGREGATE(15,6,(ROW('macs_ips'!$A$2:$A$403)-ROW(INDEX('macs_ips'!$A$2:$A$403,1,1))+1)/('macs_ips'!$E$2:$E$403=$J$1),ROW(A2))),"") | E4: =IFERROR(INDEX('macs_ips'!$E$2:$E$403,AGGREGATE(15,6,(ROW('macs_ips'!$A$2:$A$403)-ROW(INDEX('macs_ips'!$A$2:$A$403,1,1))+1)/('macs_ips'!$E$2:$E$403=$J$1),ROW(A2))),"") | F4: =IFERROR(INDEX('macs_ips'!$F$2:$F$403,AGGREGATE(15,6,(ROW('macs_ips'!$A$2:$A$403)-ROW(INDEX('macs_ips'!$A$2:$A$403,1,1))+1)/('macs_ips'!$E$2:$E$403=$J$1),ROW(A2))),"") | G4: =IFERROR(INDEX('macs_ips'!$G$2:$G$403,AGGREGATE(15,6,(ROW('macs_ips'!$A$2:$A$403)-ROW(INDEX('macs_ips'!$A$2:$A$403,1,1))+1)/('macs_ips'!$E$2:$E$403=$J$1),ROW(A2))),"")
A5: =IFERROR(INDEX('macs_ips'!$A$2:$A$403,AGGREGATE(15,6,(ROW('macs_ips'!$A$2:$A$403)-ROW(INDEX('macs_ips'!$A$2:$A$403,1,1))+1)/('macs_ips'!$E$2:$E$403=$J$1),ROW(A3))),"") | B5: =IFERROR(INDEX('macs_ips'!$B$2:$B$403,AGGREGATE(15,6,(ROW('macs_ips'!$A$2:$A$403)-ROW(INDEX('macs_ips'!$A$2:$A$403,1,1))+1)/('macs_ips'!$E$2:$E$403=$J$1),ROW(A3))),"") | C5: =IFERROR(INDEX('macs_ips'!$C$2:$C$403,AGGREGATE(15,6,(ROW('macs_ips'!$A$2:$A$403)-ROW(INDEX('macs_ips'!$A$2:$A$403,1,1))+1)/('macs_ips'!$E$2:$E$403=$J$1),ROW(A3))),"") | D5: =IFERROR(INDEX('macs_ips'!$D$2:$D$403,AGGREGATE(15,6,(ROW('macs_ips'!$A$2:$A$403)-ROW(INDEX('macs_ips'!$A$2:$A$403,1,1))+1)/('macs_ips'!$E$2:$E$403=$J$1),ROW(A3))),"") | E5: =IFERROR(INDEX('macs_ips'!$E$2:$E$403,AGGREGATE(15,6,(ROW('macs_ips'!$A$2:$A$403)-ROW(INDEX('macs_ips'!$A$2:$A$403,1,1))+1)/('macs_ips'!$E$2:$E$403=$J$1),ROW(A3))),"") | F5: =IFERROR(INDEX('macs_ips'!$F$2:$F$403,AGGREGATE(15,6,(ROW('macs_ips'!$A$2:$A$403)-ROW(INDEX('macs_ips'!$A$2:$A$403,1,1))+1)/('macs_ips'!$E$2:$E$403=$J$1),ROW(A3))),"") | G5: =IFERROR(INDEX('macs_ips'!$G$2:$G$403,AGGREGATE(15,6,(ROW('macs_ips'!$A$2:$A$403)-ROW(INDEX('macs_ips'!$A$2:$A$403,1,1))+1)/('macs_ips'!$E$2:$E$403=$J$1),ROW(A3))),"")
A6: =IFERROR(INDEX('macs_ips'!$A$2:$A$403,AGGREGATE(15,6,(ROW('macs_ips'!$A$2:$A$403)-ROW(INDEX('macs_ips'!$A$2:$A$403,1,1))+1)/('macs_ips'!$E$2:$E$403=$J$1),ROW(A4))),"") | B6: =IFERROR(INDEX('macs_ips'!$B$2:$B$403,AGGREGATE(15,6,(ROW('macs_ips'!$A$2:$A$403)-ROW(INDEX('macs_ips'!$A$2:$A$403,1,1))+1)/('macs_ips'!$E$2:$E$403=$J$1),ROW(A4))),"") | C6: =IFERROR(INDEX('macs_ips'!$C$2:$C$403,AGGREGATE(15,6,(ROW('macs_ips'!$A$2:$A$403)-ROW(INDEX('macs_ips'!$A$2:$A$403,1,1))+1)/('macs_ips'!$E$2:$E$403=$J$1),ROW(A4))),"") | D6: =IFERROR(INDEX('macs_ips'!$D$2:$D$403,AGGREGATE(15,6,(ROW('macs_ips'!$A$2:$A$403)-ROW(INDEX('macs_ips'!$A$2:$A$403,1,1))+1)/('macs_ips'!$E$2:$E$403=$J$1),ROW(A4))),"") | E6: =IFERROR(INDEX('macs_ips'!$E$2:$E$403,AGGREGATE(15,6,(ROW('macs_ips'!$A$2:$A$403)-ROW(INDEX('macs_ips'!$A$2:$A$403,1,1))+1)/('macs_ips'!$E$2:$E$403=$J$1),ROW(A4))),"") | F6: =IFERROR(INDEX('macs_ips'!$F$2:$F$403,AGGREGATE(15,6,(ROW('macs_ips'!$A$2:$A$403)-ROW(INDEX('macs_ips'!$A$2:$A$403,1,1))+1)/('macs_ips'!$E$2:$E$403=$J$1),ROW(A4))),"") | G6: =IFERROR(INDEX('macs_ips'!$G$2:$G$403,AGGREGATE(15,6,(ROW('macs_ips'!$A$2:$A$403)-ROW(INDEX('macs_ips'!$A$2:$A$403,1,1))+1)/('macs_ips'!$E$2:$E$403=$J$1),ROW(A4))),"")
A7: =IFERROR(INDEX('macs_ips'!$A$2:$A$403,AGGREGATE(15,6,(ROW('macs_ips'!$A$2:$A$403)-ROW(INDEX('macs_ips'!$A$2:$A$403,1,1))+1)/('macs_ips'!$E$2:$E$403=$J$1),ROW(A5))),"") | B7: =IFERROR(INDEX('macs_ips'!$B$2:$B$403,AGGREGATE(15,6,(ROW('macs_ips'!$A$2:$A$403)-ROW(INDEX('macs_ips'!$A$2:$A$403,1,1))+1)/('macs_ips'!$E$2:$E$403=$J$1),ROW(A5))),"") | C7: =IFERROR(INDEX('macs_ips'!$C$2:$C$403,AGGREGATE(15,6,(ROW('macs_ips'!$A$2:$A$403)-ROW(INDEX('macs_ips'!$A$2:$A$403,1,1))+1)/('macs_ips'!$E$2:$E$403=$J$1),ROW(A5))),"") | D7: =IFERROR(INDEX('macs_ips'!$D$2:$D$403,AGGREGATE(15,6,(ROW('macs_ips'!$A$2:$A$403)-ROW(INDEX('macs_ips'!$A$2:$A$403,1,1))+1)/('macs_ips'!$E$2:$E$403=$J$1),ROW(A5))),"") | E7: =IFERROR(INDEX('macs_ips'!$E$2:$E$403,AGGREGATE(15,6,(ROW('macs_ips'!$A$2:$A$403)-ROW(INDEX('macs_ips'!$A$2:$A$403,1,1))+1)/('macs_ips'!$E$2:$E$403=$J$1),ROW(A5))),"") | F7: =IFERROR(INDEX('macs_ips'!$F$2:$F$403,AGGREGATE(15,6,(ROW('macs_ips'!$A$2:$A$403)-ROW(INDEX('macs_ips'!$A$2:$A$403,1,1))+1)/('macs_ips'!$E$2:$E$403=$J$1),ROW(A5))),"") | G7: =IFERROR(INDEX('macs_ips'!$G$2:$G$403,AGGREGATE(15,6,(ROW('macs_ips'!$A$2:$A$403)-ROW(INDEX('macs_ips'!$A$2:$A$403,1,1))+1)/('macs_ips'!$E$2:$E$403=$J$1),ROW(A5))),"")
A8: =IFERROR(INDEX('macs_ips'!$A$2:$A$403,AGGREGATE(15,6,(ROW('macs_ips'!$A$2:$A$403)-ROW(INDEX('macs_ips'!$A$2:$A$403,1,1))+1)/('macs_ips'!$E$2:$E$403=$J$1),ROW(A6))),"") | B8: =IFERROR(INDEX('macs_ips'!$B$2:$B$403,AGGREGATE(15,6,(ROW('macs_ips'!$A$2:$A$403)-ROW(INDEX('macs_ips'!$A$2:$A$403,1,1))+1)/('macs_ips'!$E$2:$E$403=$J$1),ROW(A6))),"") | C8: =IFERROR(INDEX('macs_ips'!$C$2:$C$403,AGGREGATE(15,6,(ROW('macs_ips'!$A$2:$A$403)-ROW(INDEX('macs_ips'!$A$2:$A$403,1,1))+1)/('macs_ips'!$E$2:$E$403=$J$1),ROW(A6))),"") | D8: =IFERROR(INDEX('macs_ips'!$D$2:$D$403,AGGREGATE(15,6,(ROW('macs_ips'!$A$2:$A$403)-ROW(INDEX('macs_ips'!$A$2:$A$403,1,1))+1)/('macs_ips'!$E$2:$E$403=$J$1),ROW(A6))),"") | E8: =IFERROR(INDEX('macs_ips'!$E$2:$E$403,AGGREGATE(15,6,(ROW('macs_ips'!$A$2:$A$403)-ROW(INDEX('macs_ips'!$A$2:$A$403,1,1))+1)/('macs_ips'!$E$2:$E$403=$J$1),ROW(A6))),"") | F8: =IFERROR(INDEX('macs_ips'!$F$2:$F$403,AGGREGATE(15,6,(ROW('macs_ips'!$A$2:$A$403)-ROW(INDEX('macs_ips'!$A$2:$A$403,1,1))+1)/('macs_ips'!$E$2:$E$403=$J$1),ROW(A6))),"") | G8: =IFERROR(INDEX('macs_ips'!$G$2:$G$403,AGGREGATE(15,6,(ROW('macs_ips'!$A$2:$A$403)-ROW(INDEX('macs_ips'!$A$2:$A$403,1,1))+1)/('macs_ips'!$E$2:$E$403=$J$1),ROW(A6))),"")
A9: =IFERROR(INDEX('macs_ips'!$A$2:$A$403,AGGREGATE(15,6,(ROW('macs_ips'!$A$2:$A$403)-ROW(INDEX('macs_ips'!$A$2:$A$403,1,1))+1)/('macs_ips'!$E$2:$E$403=$J$1),ROW(A7))),"") | B9: =IFERROR(INDEX('macs_ips'!$B$2:$B$403,AGGREGATE(15,6,(ROW('macs_ips'!$A$2:$A$403)-ROW(INDEX('macs_ips'!$A$2:$A$403,1,1))+1)/('macs_ips'!$E$2:$E$403=$J$1),ROW(A7))),"") | C9: =IFERROR(INDEX('macs_ips'!$C$2:$C$403,AGGREGATE(15,6,(ROW('macs_ips'!$A$2:$A$403)-ROW(INDEX('macs_ips'!$A$2:$A$403,1,1))+1)/('macs_ips'!$E$2:$E$403=$J$1),ROW(A7))),"") | D9: =IFERROR(INDEX('macs_ips'!$D$2:$D$403,AGGREGATE(15,6,(ROW('macs_ips'!$A$2:$A$403)-ROW(INDEX('macs_ips'!$A$2:$A$403,1,1))+1)/('macs_ips'!$E$2:$E$403=$J$1),ROW(A7))),"") | E9: =IFERROR(INDEX('macs_ips'!$E$2:$E$403,AGGREGATE(15,6,(ROW('macs_ips'!$A$2:$A$403)-ROW(INDEX('macs_ips'!$A$2:$A$403,1,1))+1)/('macs_ips'!$E$2:$E$403=$J$1),ROW(A7))),"") | F9: =IFERROR(INDEX('macs_ips'!$F$2:$F$403,AGGREGATE(15,6,(ROW('macs_ips'!$A$2:$A$403)-ROW(INDEX('macs_ips'!$A$2:$A$403,1,1))+1)/('macs_ips'!$E$2:$E$403=$J$1),ROW(A7))),"") | G9: =IFERROR(INDEX('macs_ips'!$G$2:$G$403,AGGREGATE(15,6,(ROW('macs_ips'!$A$2:$A$403)-ROW(INDEX('macs_ips'!$A$2:$A$403,1,1))+1)/('macs_ips'!$E$2:$E$403=$J$1),ROW(A7))),"")
A10: =IFERROR(INDEX('macs_ips'!$A$2:$A$403,AGGREGATE(15,6,(ROW('macs_ips'!$A$2:$A$403)-ROW(INDEX('macs_ips'!$A$2:$A$403,1,1))+1)/('macs_ips'!$E$2:$E$403=$J$1),ROW(A8))),"") | B10: =IFERROR(INDEX('macs_ips'!$B$2:$B$403,AGGREGATE(15,6,(ROW('macs_ips'!$A$2:$A$403)-ROW(INDEX('macs_ips'!$A$2:$A$403,1,1))+1)/('macs_ips'!$E$2:$E$403=$J$1),ROW(A8))),"") | C10: =IFERROR(INDEX('macs_ips'!$C$2:$C$403,AGGREGATE(15,6,(ROW('macs_ips'!$A$2:$A$403)-ROW(INDEX('macs_ips'!$A$2:$A$403,1,1))+1)/('macs_ips'!$E$2:$E$403=$J$1),ROW(A8))),"") | D10: =IFERROR(INDEX('macs_ips'!$D$2:$D$403,AGGREGATE(15,6,(ROW('macs_ips'!$A$2:$A$403)-ROW(INDEX('macs_ips'!$A$2:$A$403,1,1))+1)/('macs_ips'!$E$2:$E$403=$J$1),ROW(A8))),"") | E10: =IFERROR(INDEX('macs_ips'!$E$2:$E$403,AGGREGATE(15,6,(ROW('macs_ips'!$A$2:$A$403)-ROW(INDEX('macs_ips'!$A$2:$A$403,1,1))+1)/('macs_ips'!$E$2:$E$403=$J$1),ROW(A8))),"") | F10: =IFERROR(INDEX('macs_ips'!$F$2:$F$403,AGGREGATE(15,6,(ROW('macs_ips'!$A$2:$A$403)-ROW(INDEX('macs_ips'!$A$2:$A$403,1,1))+1)/('macs_ips'!$E$2:$E$403=$J$1),ROW(A8))),"") | G10: =IFERROR(INDEX('macs_ips'!$G$2:$G$403,AGGREGATE(15,6,(ROW('macs_ips'!$A$2:$A$403)-ROW(INDEX('macs_ips'!$A$2:$A$403,1,1))+1)/('macs_ips'!$E$2:$E$403=$J$1),ROW(A8))),"")
A11: =IFERROR(INDEX('macs_ips'!$A$2:$A$403,AGGREGATE(15,6,(ROW('macs_ips'!$A$2:$A$403)-ROW(INDEX('macs_ips'!$A$2:$A$403,1,1))+1)/('macs_ips'!$E$2:$E$403=$J$1),ROW(A9))),"") | B11: =IFERROR(INDEX('macs_ips'!$B$2:$B$403,AGGREGATE(15,6,(ROW('macs_ips'!$A$2:$A$403)-ROW(INDEX('macs_ips'!$A$2:$A$403,1,1))+1)/('macs_ips'!$E$2:$E$403=$J$1),ROW(A9))),"") | C11: =IFERROR(INDEX('macs_ips'!$C$2:$C$403,AGGREGATE(15,6,(ROW('macs_ips'!$A$2:$A$403)-ROW(INDEX('macs_ips'!$A$2:$A$403,1,1))+1)/('macs_ips'!$E$2:$E$403=$J$1),ROW(A9))),"") | D11: =IFERROR(INDEX('macs_ips'!$D$2:$D$403,AGGREGATE(15,6,(ROW('macs_ips'!$A$2:$A$403)-ROW(INDEX('macs_ips'!$A$2:$A$403,1,1))+1)/('macs_ips'!$E$2:$E$403=$J$1),ROW(A9))),"") | E11: =IFERROR(INDEX('macs_ips'!$E$2:$E$403,AGGREGATE(15,6,(ROW('macs_ips'!$A$2:$A$403)-ROW(INDEX('macs_ips'!$A$2:$A$403,1,1))+1)/('macs_ips'!$E$2:$E$403=$J$1),ROW(A9))),"") | F11: =IFERROR(INDEX('macs_ips'!$F$2:$F$403,AGGREGATE(15,6,(ROW('macs_ips'!$A$2:$A$403)-ROW(INDEX('macs_ips'!$A$2:$A$403,1,1))+1)/('macs_ips'!$E$2:$E$403=$J$1),ROW(A9))),"") | G11: =IFERROR(INDEX('macs_ips'!$G$2:$G$403,AGGREGATE(15,6,(ROW('macs_ips'!$A$2:$A$403)-ROW(INDEX('macs_ips'!$A$2:$A$403,1,1))+1)/('macs_ips'!$E$2:$E$403=$J$1),ROW(A9))),"")
A12: =IFERROR(INDEX('macs_ips'!$A$2:$A$403,AGGREGATE(15,6,(ROW('macs_ips'!$A$2:$A$403)-ROW(INDEX('macs_ips'!$A$2:$A$403,1,1))+1)/('macs_ips'!$E$2:$E$403=$J$1),ROW(A10))),"") | B12: =IFERROR(INDEX('macs_ips'!$B$2:$B$403,AGGREGATE(15,6,(ROW('macs_ips'!$A$2:$A$403)-ROW(INDEX('macs_ips'!$A$2:$A$403,1,1))+1)/('macs_ips'!$E$2:$E$403=$J$1),ROW(A10))),"") | C12: =IFERROR(INDEX('macs_ips'!$C$2:$C$403,AGGREGATE(15,6,(ROW('macs_ips'!$A$2:$A$403)-ROW(INDEX('macs_ips'!$A$2:$A$403,1,1))+1)/('macs_ips'!$E$2:$E$403=$J$1),ROW(A10))),"") | D12: =IFERROR(INDEX('macs_ips'!$D$2:$D$403,AGGREGATE(15,6,(ROW('macs_ips'!$A$2:$A$403)-ROW(INDEX('macs_ips'!$A$2:$A$403,1,1))+1)/('macs_ips'!$E$2:$E$403=$J$1),ROW(A10))),"") | E12: =IFERROR(INDEX('macs_ips'!$E$2:$E$403,AGGREGATE(15,6,(ROW('macs_ips'!$A$2:$A$403)-ROW(INDEX('macs_ips'!$A$2:$A$403,1,1))+1)/('macs_ips'!$E$2:$E$403=$J$1),ROW(A10))),"") | F12: =IFERROR(INDEX('macs_ips'!$F$2:$F$403,AGGREGATE(15,6,(ROW('macs_ips'!$A$2:$A$403)-ROW(INDEX('macs_ips'!$A$2:$A$403,1,1))+1)/('macs_ips'!$E$2:$E$403=$J$1),ROW(A10))),"") | G12: =IFERROR(INDEX('macs_ips'!$G$2:$G$403,AGGREGATE(15,6,(ROW('macs_ips'!$A$2:$A$403)-ROW(INDEX('macs_ips'!$A$2:$A$403,1,1))+1)/('macs_ips'!$E$2:$E$403=$J$1),ROW(A10))),"")
A13: =IFERROR(INDEX('macs_ips'!$A$2:$A$403,AGGREGATE(15,6,(ROW('macs_ips'!$A$2:$A$403)-ROW(INDEX('macs_ips'!$A$2:$A$403,1,1))+1)/('macs_ips'!$E$2:$E$403=$J$1),ROW(A11))),"") | B13: =IFERROR(INDEX('macs_ips'!$B$2:$B$403,AGGREGATE(15,6,(ROW('macs_ips'!$A$2:$A$403)-ROW(INDEX('macs_ips'!$A$2:$A$403,1,1))+1)/('macs_ips'!$E$2:$E$403=$J$1),ROW(A11))),"") | C13: =IFERROR(INDEX('macs_ips'!$C$2:$C$403,AGGREGATE(15,6,(ROW('macs_ips'!$A$2:$A$403)-ROW(INDEX('macs_ips'!$A$2:$A$403,1,1))+1)/('macs_ips'!$E$2:$E$403=$J$1),ROW(A11))),"") | D13: =IFERROR(INDEX('macs_ips'!$D$2:$D$403,AGGREGATE(15,6,(ROW('macs_ips'!$A$2:$A$403)-ROW(INDEX('macs_ips'!$A$2:$A$403,1,1))+1)/('macs_ips'!$E$2:$E$403=$J$1),ROW(A11))),"") | E13: =IFERROR(INDEX('macs_ips'!$E$2:$E$403,AGGREGATE(15,6,(ROW('macs_ips'!$A$2:$A$403)-ROW(INDEX('macs_ips'!$A$2:$A$403,1,1))+1)/('macs_ips'!$E$2:$E$403=$J$1),ROW(A11))),"") | F13: =IFERROR(INDEX('macs_ips'!$F$2:$F$403,AGGREGATE(15,6,(ROW('macs_ips'!$A$2:$A$403)-ROW(INDEX('macs_ips'!$A$2:$A$403,1,1))+1)/('macs_ips'!$E$2:$E$403=$J$1),ROW(A11))),"") | G13: =IFERROR(INDEX('macs_ips'!$G$2:$G$403,AGGREGATE(15,6,(ROW('macs_ips'!$A$2:$A$403)-ROW(INDEX('macs_ips'!$A$2:$A$403,1,1))+1)/('macs_ips'!$E$2:$E$403=$J$1),ROW(A11))),"")
A14: =IFERROR(INDEX('macs_ips'!$A$2:$A$403,AGGREGATE(15,6,(ROW('macs_ips'!$A$2:$A$403)-ROW(INDEX('macs_ips'!$A$2:$A$403,1,1))+1)/('macs_ips'!$E$2:$E$403=$J$1),ROW(A12))),"") | B14: =IFERROR(INDEX('macs_ips'!$B$2:$B$403,AGGREGATE(15,6,(ROW('macs_ips'!$A$2:$A$403)-ROW(INDEX('macs_ips'!$A$2:$A$403,1,1))+1)/('macs_ips'!$E$2:$E$403=$J$1),ROW(A12))),"") | C14: =IFERROR(INDEX('macs_ips'!$C$2:$C$403,AGGREGATE(15,6,(ROW('macs_ips'!$A$2:$A$403)-ROW(INDEX('macs_ips'!$A$2:$A$403,1,1))+1)/('macs_ips'!$E$2:$E$403=$J$1),ROW(A12))),"") | D14: =IFERROR(INDEX('macs_ips'!$D$2:$D$403,AGGREGATE(15,6,(ROW('macs_ips'!$A$2:$A$403)-ROW(INDEX('macs_ips'!$A$2:$A$403,1,1))+1)/('macs_ips'!$E$2:$E$403=$J$1),ROW(A12))),"") | E14: =IFERROR(INDEX('macs_ips'!$E$2:$E$403,AGGREGATE(15,6,(ROW('macs_ips'!$A$2:$A$403)-ROW(INDEX('macs_ips'!$A$2:$A$403,1,1))+1)/('macs_ips'!$E$2:$E$403=$J$1),ROW(A12))),"") | F14: =IFERROR(INDEX('macs_ips'!$F$2:$F$403,AGGREGATE(15,6,(ROW('macs_ips'!$A$2:$A$403)-ROW(INDEX('macs_ips'!$A$2:$A$403,1,1))+1)/('macs_ips'!$E$2:$E$403=$J$1),ROW(A12))),"") | G14: =IFERROR(INDEX('macs_ips'!$G$2:$G$403,AGGREGATE(15,6,(ROW('macs_ips'!$A$2:$A$403)-ROW(INDEX('macs_ips'!$A$2:$A$403,1,1))+1)/('macs_ips'!$E$2:$E$403=$J$1),ROW(A12))),"")
... A452: =IFERROR(INDEX('macs_ips'!$A$2:$A$403,AGGREGATE(15,6,(ROW('macs_ips'!$A$2:$A$403)-ROW(INDEX('macs_ips'!$A$2:$A$403,1,1))+1)/('macs_ips'!$E$2:$E$403=$J$1),ROW(A450))),"") | B452: =IFERROR(INDEX('macs_ips'!$B$2:$B$403,AGGREGATE(15,6,(ROW('macs_ips'!$A$2:$A$403)-ROW(INDEX('macs_ips'!$A$2:$A$403,1,1))+1)/('macs_ips'!$E$2:$E$403=$J$1),ROW(A450))),"") | C452: =IFERROR(INDEX('macs_ips'!$C$2:$C$403,AGGREGATE(15,6,(ROW('macs_ips'!$A$2:$A$403)-ROW(INDEX('macs_ips'!$A$2:$A$403,1,1))+1)/('macs_ips'!$E$2:$E$403=$J$1),ROW(A450))),"") | D452: =IFERROR(INDEX('macs_ips'!$D$2:$D$403,AGGREGATE(15,6,(ROW('macs_ips'!$A$2:$A$403)-ROW(INDEX('macs_ips'!$A$2:$A$403,1,1))+1)/('macs_ips'!$E$2:$E$403=$J$1),ROW(A450))),"") | E452: =IFERROR(INDEX('macs_ips'!$E$2:$E$403,AGGREGATE(15,6,(ROW('macs_ips'!$A$2:$A$403)-ROW(INDEX('macs_ips'!$A$2:$A$403,1,1))+1)/('macs_ips'!$E$2:$E$403=$J$1),ROW(A450))),"") | F452: =IFERROR(INDEX('macs_ips'!$F$2:$F$403,AGGREGATE(15,6,(ROW('macs_ips'!$A$2:$A$403)-ROW(INDEX('macs_ips'!$A$2:$A$403,1,1))+1)/('macs_ips'!$E$2:$E$403=$J$1),ROW(A450))),"") | G452: =IFERROR(INDEX('macs_ips'!$G$2:$G$403,AGGREGATE(15,6,(ROW('macs_ips'!$A$2:$A$403)-ROW(INDEX('macs_ips'!$A$2:$A$403,1,1))+1)/('macs_ips'!$E$2:$E$403=$J$1),ROW(A450))),"")

Sheet SEM_CONTACTO
A1: CLIENTES — Sem contacto | J1: Sem contacto
A2: MAC | B2: Ips | C2: Contactos | D2: data exp | E2: Situação | F2: data da proxima ação | G2: observação
A3: =IFERROR(INDEX('macs_ips'!$A$2:$A$403,AGGREGATE(15,6,(ROW('macs_ips'!$A$2:$A$403)-ROW(INDEX('macs_ips'!$A$2:$A$403,1,1))+1)/('macs_ips'!$E$2:$E$403=$J$1),ROW(A1))),"") | B3: =IFERROR(INDEX('macs_ips'!$B$2:$B$403,AGGREGATE(15,6,(ROW('macs_ips'!$A$2:$A$403)-ROW(INDEX('macs_ips'!$A$2:$A$403,1,1))+1)/('macs_ips'!$E$2:$E$403=$J$1),ROW(A1))),"") | C3: =IFERROR(INDEX('macs_ips'!$C$2:$C$403,AGGREGATE(15,6,(ROW('macs_ips'!$A$2:$A$403)-ROW(INDEX('macs_ips'!$A$2:$A$403,1,1))+1)/('macs_ips'!$E$2:$E$403=$J$1),ROW(A1))),"") | D3: =IFERROR(INDEX('macs_ips'!$D$2:$D$403,AGGREGATE(15,6,(ROW('macs_ips'!$A$2:$A$403)-ROW(INDEX('macs_ips'!$A$2:$A$403,1,1))+1)/('macs_ips'!$E$2:$E$403=$J$1),ROW(A1))),"") | E3: =IFERROR(INDEX('macs_ips'!$E$2:$E$403,AGGREGATE(15,6,(ROW('macs_ips'!$A$2:$A$403)-ROW(INDEX('macs_ips'!$A$2:$A$403,1,1))+1)/('macs_ips'!$E$2:$E$403=$J$1),ROW(A1))),"") | F3: =IFERROR(INDEX('macs_ips'!$F$2:$F$403,AGGREGATE(15,6,(ROW('macs_ips'!$A$2:$A$403)-ROW(INDEX('macs_ips'!$A$2:$A$403,1,1))+1)/('macs_ips'!$E$2:$E$403=$J$1),ROW(A1))),"") | G3: =IFERROR(INDEX('macs_ips'!$G$2:$G$403,AGGREGATE(15,6,(ROW('macs_ips'!$A$2:$A$403)-ROW(INDEX('macs_ips'!$A$2:$A$403,1,1))+1)/('macs_ips'!$E$2:$E$403=$J$1),ROW(A1))),"")
A4: =IFERROR(INDEX('macs_ips'!$A$2:$A$403,AGGREGATE(15,6,(ROW('macs_ips'!$A$2:$A$403)-ROW(INDEX('macs_ips'!$A$2:$A$403,1,1))+1)/('macs_ips'!$E$2:$E$403=$J$1),ROW(A2))),"") | B4: =IFERROR(INDEX('macs_ips'!$B$2:$B$403,AGGREGATE(15,6,(ROW('macs_ips'!$A$2:$A$403)-ROW(INDEX('macs_ips'!$A$2:$A$403,1,1))+1)/('macs_ips'!$E$2:$E$403=$J$1),ROW(A2))),"") | C4: =IFERROR(INDEX('macs_ips'!$C$2:$C$403,AGGREGATE(15,6,(ROW('macs_ips'!$A$2:$A$403)-ROW(INDEX('macs_ips'!$A$2:$A$403,1,1))+1)/('macs_ips'!$E$2:$E$403=$J$1),ROW(A2))),"") | D4: =IFERROR(INDEX('macs_ips'!$D$2:$D$403,AGGREGATE(15,6,(ROW('macs_ips'!$A$2:$A$403)-ROW(INDEX('macs_ips'!$A$2:$A$403,1,1))+1)/('macs_ips'!$E$2:$E$403=$J$1),ROW(A2))),"") | E4: =IFERROR(INDEX('macs_ips'!$E$2:$E$403,AGGREGATE(15,6,(ROW('macs_ips'!$A$2:$A$403)-ROW(INDEX('macs_ips'!$A$2:$A$403,1,1))+1)/('macs_ips'!$E$2:$E$403=$J$1),ROW(A2))),"") | F4: =IFERROR(INDEX('macs_ips'!$F$2:$F$403,AGGREGATE(15,6,(ROW('macs_ips'!$A$2:$A$403)-ROW(INDEX('macs_ips'!$A$2:$A$403,1,1))+1)/('macs_ips'!$E$2:$E$403=$J$1),ROW(A2))),"") | G4: =IFERROR(INDEX('macs_ips'!$G$2:$G$403,AGGREGATE(15,6,(ROW('macs_ips'!$A$2:$A$403)-ROW(INDEX('macs_ips'!$A$2:$A$403,1,1))+1)/('macs_ips'!$E$2:$E$403=$J$1),ROW(A2))),"")
A5: =IFERROR(INDEX('macs_ips'!$A$2:$A$403,AGGREGATE(15,6,(ROW('macs_ips'!$A$2:$A$403)-ROW(INDEX('macs_ips'!$A$2:$A$403,1,1))+1)/('macs_ips'!$E$2:$E$403=$J$1),ROW(A3))),"") | B5: =IFERROR(INDEX('macs_ips'!$B$2:$B$403,AGGREGATE(15,6,(ROW('macs_ips'!$A$2:$A$403)-ROW(INDEX('macs_ips'!$A$2:$A$403,1,1))+1)/('macs_ips'!$E$2:$E$403=$J$1),ROW(A3))),"") | C5: =IFERROR(INDEX('macs_ips'!$C$2:$C$403,AGGREGATE(15,6,(ROW('macs_ips'!$A$2:$A$403)-ROW(INDEX('macs_ips'!$A$2:$A$403,1,1))+1)/('macs_ips'!$E$2:$E$403=$J$1),ROW(A3))),"") | D5: =IFERROR(INDEX('macs_ips'!$D$2:$D$403,AGGREGATE(15,6,(ROW('macs_ips'!$A$2:$A$403)-ROW(INDEX('macs_ips'!$A$2:$A$403,1,1))+1)/('macs_ips'!$E$2:$E$403=$J$1),ROW(A3))),"") | E5: =IFERROR(INDEX('macs_ips'!$E$2:$E$403,AGGREGATE(15,6,(ROW('macs_ips'!$A$2:$A$403)-ROW(INDEX('macs_ips'!$A$2:$A$403,1,1))+1)/('macs_ips'!$E$2:$E$403=$J$1),ROW(A3))),"") | F5: =IFERROR(INDEX('macs_ips'!$F$2:$F$403,AGGREGATE(15,6,(ROW('macs_ips'!$A$2:$A$403)-ROW(INDEX('macs_ips'!$A$2:$A$403,1,1))+1)/('macs_ips'!$E$2:$E$403=$J$1),ROW(A3))),"") | G5: =IFERROR(INDEX('macs_ips'!$G$2:$G$403,AGGREGATE(15,6,(ROW('macs_ips'!$A$2:$A$403)-ROW(INDEX('macs_ips'!$A$2:$A$403,1,1))+1)/('macs_ips'!$E$2:$E$403=$J$1),ROW(A3))),"")
A6: =IFERROR(INDEX('macs_ips'!$A$2:$A$403,AGGREGATE(15,6,(ROW('macs_ips'!$A$2:$A$403)-ROW(INDEX('macs_ips'!$A$2:$A$403,1,1))+1)/('macs_ips'!$E$2:$E$403=$J$1),ROW(A4))),"") | B6: =IFERROR(INDEX('macs_ips'!$B$2:$B$403,AGGREGATE(15,6,(ROW('macs_ips'!$A$2:$A$403)-ROW(INDEX('macs_ips'!$A$2:$A$403,1,1))+1)/('macs_ips'!$E$2:$E$403=$J$1),ROW(A4))),"") | C6: =IFERROR(INDEX('macs_ips'!$C$2:$C$403,AGGREGATE(15,6,(ROW('macs_ips'!$A$2:$A$403)-ROW(INDEX('macs_ips'!$A$2:$A$403,1,1))+1)/('macs_ips'!$E$2:$E$403=$J$1),ROW(A4))),"") | D6: =IFERROR(INDEX('macs_ips'!$D$2:$D$403,AGGREGATE(15,6,(ROW('macs_ips'!$A$2:$A$403)-ROW(INDEX('macs_ips'!$A$2:$A$403,1,1))+1)/('macs_ips'!$E$2:$E$403=$J$1),ROW(A4))),"") | E6: =IFERROR(INDEX('macs_ips'!$E$2:$E$403,AGGREGATE(15,6,(ROW('macs_ips'!$A$2:$A$403)-ROW(INDEX('macs_ips'!$A$2:$A$403,1,1))+1)/('macs_ips'!$E$2:$E$403=$J$1),ROW(A4))),"") | F6: =IFERROR(INDEX('macs_ips'!$F$2:$F$403,AGGREGATE(15,6,(ROW('macs_ips'!$A$2:$A$403)-ROW(INDEX('macs_ips'!$A$2:$A$403,1,1))+1)/('macs_ips'!$E$2:$E$403=$J$1),ROW(A4))),"") | G6: =IFERROR(INDEX('macs_ips'!$G$2:$G$403,AGGREGATE(15,6,(ROW('macs_ips'!$A$2:$A$403)-ROW(INDEX('macs_ips'!$A$2:$A$403,1,1))+1)/('macs_ips'!$E$2:$E$403=$J$1),ROW(A4))),"")
A7: =IFERROR(INDEX('macs_ips'!$A$2:$A$403,AGGREGATE(15,6,(ROW('macs_ips'!$A$2:$A$403)-ROW(INDEX('macs_ips'!$A$2:$A$403,1,1))+1)/('macs_ips'!$E$2:$E$403=$J$1),ROW(A5))),"") | B7: =IFERROR(INDEX('macs_ips'!$B$2:$B$403,AGGREGATE(15,6,(ROW('macs_ips'!$A$2:$A$403)-ROW(INDEX('macs_ips'!$A$2:$A$403,1,1))+1)/('macs_ips'!$E$2:$E$403=$J$1),ROW(A5))),"") | C7: =IFERROR(INDEX('macs_ips'!$C$2:$C$403,AGGREGATE(15,6,(ROW('macs_ips'!$A$2:$A$403)-ROW(INDEX('macs_ips'!$A$2:$A$403,1,1))+1)/('macs_ips'!$E$2:$E$403=$J$1),ROW(A5))),"") | D7: =IFERROR(INDEX('macs_ips'!$D$2:$D$403,AGGREGATE(15,6,(ROW('macs_ips'!$A$2:$A$403)-ROW(INDEX('macs_ips'!$A$2:$A$403,1,1))+1)/('macs_ips'!$E$2:$E$403=$J$1),ROW(A5))),"") | E7: =IFERROR(INDEX('macs_ips'!$E$2:$E$403,AGGREGATE(15,6,(ROW('macs_ips'!$A$2:$A$403)-ROW(INDEX('macs_ips'!$A$2:$A$403,1,1))+1)/('macs_ips'!$E$2:$E$403=$J$1),ROW(A5))),"") | F7: =IFERROR(INDEX('macs_ips'!$F$2:$F$403,AGGREGATE(15,6,(ROW('macs_ips'!$A$2:$A$403)-ROW(INDEX('macs_ips'!$A$2:$A$403,1,1))+1)/('macs_ips'!$E$2:$E$403=$J$1),ROW(A5))),"") | G7: =IFERROR(INDEX('macs_ips'!$G$2:$G$403,AGGREGATE(15,6,(ROW('macs_ips'!$A$2:$A$403)-ROW(INDEX('macs_ips'!$A$2:$A$403,1,1))+1)/('macs_ips'!$E$2:$E$403=$J$1),ROW(A5))),"")
A8: =IFERROR(INDEX('macs_ips'!$A$2:$A$403,AGGREGATE(15,6,(ROW('macs_ips'!$A$2:$A$403)-ROW(INDEX('macs_ips'!$A$2:$A$403,1,1))+1)/('macs_ips'!$E$2:$E$403=$J$1),ROW(A6))),"") | B8: =IFERROR(INDEX('macs_ips'!$B$2:$B$403,AGGREGATE(15,6,(ROW('macs_ips'!$A$2:$A$403)-ROW(INDEX('macs_ips'!$A$2:$A$403,1,1))+1)/('macs_ips'!$E$2:$E$403=$J$1),ROW(A6))),"") | C8: =IFERROR(INDEX('macs_ips'!$C$2:$C$403,AGGREGATE(15,6,(ROW('macs_ips'!$A$2:$A$403)-ROW(INDEX('macs_ips'!$A$2:$A$403,1,1))+1)/('macs_ips'!$E$2:$E$403=$J$1),ROW(A6))),"") | D8: =IFERROR(INDEX('macs_ips'!$D$2:$D$403,AGGREGATE(15,6,(ROW('macs_ips'!$A$2:$A$403)-ROW(INDEX('macs_ips'!$A$2:$A$403,1,1))+1)/('macs_ips'!$E$2:$E$403=$J$1),ROW(A6))),"") | E8: =IFERROR(INDEX('macs_ips'!$E$2:$E$403,AGGREGATE(15,6,(ROW('macs_ips'!$A$2:$A$403)-ROW(INDEX('macs_ips'!$A$2:$A$403,1,1))+1)/('macs_ips'!$E$2:$E$403=$J$1),ROW(A6))),"") | F8: =IFERROR(INDEX('macs_ips'!$F$2:$F$403,AGGREGATE(15,6,(ROW('macs_ips'!$A$2:$A$403)-ROW(INDEX('macs_ips'!$A$2:$A$403,1,1))+1)/('macs_ips'!$E$2:$E$403=$J$1),ROW(A6))),"") | G8: =IFERROR(INDEX('macs_ips'!$G$2:$G$403,AGGREGATE(15,6,(ROW('macs_ips'!$A$2:$A$403)-ROW(INDEX('macs_ips'!$A$2:$A$403,1,1))+1)/('macs_ips'!$E$2:$E$403=$J$1),ROW(A6))),"")
A9: =IFERROR(INDEX('macs_ips'!$A$2:$A$403,AGGREGATE(15,6,(ROW('macs_ips'!$A$2:$A$403)-ROW(INDEX('macs_ips'!$A$2:$A$403,1,1))+1)/('macs_ips'!$E$2:$E$403=$J$1),ROW(A7))),"") | B9: =IFERROR(INDEX('macs_ips'!$B$2:$B$403,AGGREGATE(15,6,(ROW('macs_ips'!$A$2:$A$403)-ROW(INDEX('macs_ips'!$A$2:$A$403,1,1))+1)/('macs_ips'!$E$2:$E$403=$J$1),ROW(A7))),"") | C9: =IFERROR(INDEX('macs_ips'!$C$2:$C$403,AGGREGATE(15,6,(ROW('macs_ips'!$A$2:$A$403)-ROW(INDEX('macs_ips'!$A$2:$A$403,1,1))+1)/('macs_ips'!$E$2:$E$403=$J$1),ROW(A7))),"") | D9: =IFERROR(INDEX('macs_ips'!$D$2:$D$403,AGGREGATE(15,6,(ROW('macs_ips'!$A$2:$A$403)-ROW(INDEX('macs_ips'!$A$2:$A$403,1,1))+1)/('macs_ips'!$E$2:$E$403=$J$1),ROW(A7))),"") | E9: =IFERROR(INDEX('macs_ips'!$E$2:$E$403,AGGREGATE(15,6,(ROW('macs_ips'!$A$2:$A$403)-ROW(INDEX('macs_ips'!$A$2:$A$403,1,1))+1)/('macs_ips'!$E$2:$E$403=$J$1),ROW(A7))),"") | F9: =IFERROR(INDEX('macs_ips'!$F$2:$F$403,AGGREGATE(15,6,(ROW('macs_ips'!$A$2:$A$403)-ROW(INDEX('macs_ips'!$A$2:$A$403,1,1))+1)/('macs_ips'!$E$2:$E$403=$J$1),ROW(A7))),"") | G9: =IFERROR(INDEX('macs_ips'!$G$2:$G$403,AGGREGATE(15,6,(ROW('macs_ips'!$A$2:$A$403)-ROW(INDEX('macs_ips'!$A$2:$A$403,1,1))+1)/('macs_ips'!$E$2:$E$403=$J$1),ROW(A7))),"")
A10: =IFERROR(INDEX('macs_ips'!$A$2:$A$403,AGGREGATE(15,6,(ROW('macs_ips'!$A$2:$A$403)-ROW(INDEX('macs_ips'!$A$2:$A$403,1,1))+1)/('macs_ips'!$E$2:$E$403=$J$1),ROW(A8))),"") | B10: =IFERROR(INDEX('macs_ips'!$B$2:$B$403,AGGREGATE(15,6,(ROW('macs_ips'!$A$2:$A$403)-ROW(INDEX('macs_ips'!$A$2:$A$403,1,1))+1)/('macs_ips'!$E$2:$E$403=$J$1),ROW(A8))),"") | C10: =IFERROR(INDEX('macs_ips'!$C$2:$C$403,AGGREGATE(15,6,(ROW('macs_ips'!$A$2:$A$403)-ROW(INDEX('macs_ips'!$A$2:$A$403,1,1))+1)/('macs_ips'!$E$2:$E$403=$J$1),ROW(A8))),"") | D10: =IFERROR(INDEX('macs_ips'!$D$2:$D$403,AGGREGATE(15,6,(ROW('macs_ips'!$A$2:$A$403)-ROW(INDEX('macs_ips'!$A$2:$A$403,1,1))+1)/('macs_ips'!$E$2:$E$403=$J$1),ROW(A8))),"") | E10: =IFERROR(INDEX('macs_ips'!$E$2:$E$403,AGGREGATE(15,6,(ROW('macs_ips'!$A$2:$A$403)-ROW(INDEX('macs_ips'!$A$2:$A$403,1,1))+1)/('macs_ips'!$E$2:$E$403=$J$1),ROW(A8))),"") | F10: =IFERROR(INDEX('macs_ips'!$F$2:$F$403,AGGREGATE(15,6,(ROW('macs_ips'!$A$2:$A$403)-ROW(INDEX('macs_ips'!$A$2:$A$403,1,1))+1)/('macs_ips'!$E$2:$E$403=$J$1),ROW(A8))),"") | G10: =IFERROR(INDEX('macs_ips'!$G$2:$G$403,AGGREGATE(15,6,(ROW('macs_ips'!$A$2:$A$403)-ROW(INDEX('macs_ips'!$A$2:$A$403,1,1))+1)/('macs_ips'!$E$2:$E$403=$J$1),ROW(A8))),"")
A11: =IFERROR(INDEX('macs_ips'!$A$2:$A$403,AGGREGATE(15,6,(ROW('macs_ips'!$A$2:$A$403)-ROW(INDEX('macs_ips'!$A$2:$A$403,1,1))+1)/('macs_ips'!$E$2:$E$403=$J$1),ROW(A9))),"") | B11: =IFERROR(INDEX('macs_ips'!$B$2:$B$403,AGGREGATE(15,6,(ROW('macs_ips'!$A$2:$A$403)-ROW(INDEX('macs_ips'!$A$2:$A$403,1,1))+1)/('macs_ips'!$E$2:$E$403=$J$1),ROW(A9))),"") | C11: =IFERROR(INDEX('macs_ips'!$C$2:$C$403,AGGREGATE(15,6,(ROW('macs_ips'!$A$2:$A$403)-ROW(INDEX('macs_ips'!$A$2:$A$403,1,1))+1)/('macs_ips'!$E$2:$E$403=$J$1),ROW(A9))),"") | D11: =IFERROR(INDEX('macs_ips'!$D$2:$D$403,AGGREGATE(15,6,(ROW('macs_ips'!$A$2:$A$403)-ROW(INDEX('macs_ips'!$A$2:$A$403,1,1))+1)/('macs_ips'!$E$2:$E$403=$J$1),ROW(A9))),"") | E11: =IFERROR(INDEX('macs_ips'!$E$2:$E$403,AGGREGATE(15,6,(ROW('macs_ips'!$A$2:$A$403)-ROW(INDEX('macs_ips'!$A$2:$A$403,1,1))+1)/('macs_ips'!$E$2:$E$403=$J$1),ROW(A9))),"") | F11: =IFERROR(INDEX('macs_ips'!$F$2:$F$403,AGGREGATE(15,6,(ROW('macs_ips'!$A$2:$A$403)-ROW(INDEX('macs_ips'!$A$2:$A$403,1,1))+1)/('macs_ips'!$E$2:$E$403=$J$1),ROW(A9))),"") | G11: =IFERROR(INDEX('macs_ips'!$G$2:$G$403,AGGREGATE(15,6,(ROW('macs_ips'!$A$2:$A$403)-ROW(INDEX('macs_ips'!$A$2:$A$403,1,1))+1)/('macs_ips'!$E$2:$E$403=$J$1),ROW(A9))),"")
A12: =IFERROR(INDEX('macs_ips'!$A$2:$A$403,AGGREGATE(15,6,(ROW('macs_ips'!$A$2:$A$403)-ROW(INDEX('macs_ips'!$A$2:$A$403,1,1))+1)/('macs_ips'!$E$2:$E$403=$J$1),ROW(A10))),"") | B12: =IFERROR(INDEX('macs_ips'!$B$2:$B$403,AGGREGATE(15,6,(ROW('macs_ips'!$A$2:$A$403)-ROW(INDEX('macs_ips'!$A$2:$A$403,1,1))+1)/('macs_ips'!$E$2:$E$403=$J$1),ROW(A10))),"") | C12: =IFERROR(INDEX('macs_ips'!$C$2:$C$403,AGGREGATE(15,6,(ROW('macs_ips'!$A$2:$A$403)-ROW(INDEX('macs_ips'!$A$2:$A$403,1,1))+1)/('macs_ips'!$E$2:$E$403=$J$1),ROW(A10))),"") | D12: =IFERROR(INDEX('macs_ips'!$D$2:$D$403,AGGREGATE(15,6,(ROW('macs_ips'!$A$2:$A$403)-ROW(INDEX('macs_ips'!$A$2:$A$403,1,1))+1)/('macs_ips'!$E$2:$E$403=$J$1),ROW(A10))),"") | E12: =IFERROR(INDEX('macs_ips'!$E$2:$E$403,AGGREGATE(15,6,(ROW('macs_ips'!$A$2:$A$403)-ROW(INDEX('macs_ips'!$A$2:$A$403,1,1))+1)/('macs_ips'!$E$2:$E$403=$J$1),ROW(A10))),"") | F12: =IFERROR(INDEX('macs_ips'!$F$2:$F$403,AGGREGATE(15,6,(ROW('macs_ips'!$A$2:$A$403)-ROW(INDEX('macs_ips'!$A$2:$A$403,1,1))+1)/('macs_ips'!$E$2:$E$403=$J$1),ROW(A10))),"") | G12: =IFERROR(INDEX('macs_ips'!$G$2:$G$403,AGGREGATE(15,6,(ROW('macs_ips'!$A$2:$A$403)-ROW(INDEX('macs_ips'!$A$2:$A$403,1,1))+1)/('macs_ips'!$E$2:$E$403=$J$1),ROW(A10))),"")
A13: =IFERROR(INDEX('macs_ips'!$A$2:$A$403,AGGREGATE(15,6,(ROW('macs_ips'!$A$2:$A$403)-ROW(INDEX('macs_ips'!$A$2:$A$403,1,1))+1)/('macs_ips'!$E$2:$E$403=$J$1),ROW(A11))),"") | B13: =IFERROR(INDEX('macs_ips'!$B$2:$B$403,AGGREGATE(15,6,(ROW('macs_ips'!$A$2:$A$403)-ROW(INDEX('macs_ips'!$A$2:$A$403,1,1))+1)/('macs_ips'!$E$2:$E$403=$J$1),ROW(A11))),"") | C13: =IFERROR(INDEX('macs_ips'!$C$2:$C$403,AGGREGATE(15,6,(ROW('macs_ips'!$A$2:$A$403)-ROW(INDEX('macs_ips'!$A$2:$A$403,1,1))+1)/('macs_ips'!$E$2:$E$403=$J$1),ROW(A11))),"") | D13: =IFERROR(INDEX('macs_ips'!$D$2:$D$403,AGGREGATE(15,6,(ROW('macs_ips'!$A$2:$A$403)-ROW(INDEX('macs_ips'!$A$2:$A$403,1,1))+1)/('macs_ips'!$E$2:$E$403=$J$1),ROW(A11))),"") | E13: =IFERROR(INDEX('macs_ips'!$E$2:$E$403,AGGREGATE(15,6,(ROW('macs_ips'!$A$2:$A$403)-ROW(INDEX('macs_ips'!$A$2:$A$403,1,1))+1)/('macs_ips'!$E$2:$E$403=$J$1),ROW(A11))),"") | F13: =IFERROR(INDEX('macs_ips'!$F$2:$F$403,AGGREGATE(15,6,(ROW('macs_ips'!$A$2:$A$403)-ROW(INDEX('macs_ips'!$A$2:$A$403,1,1))+1)/('macs_ips'!$E$2:$E$403=$J$1),ROW(A11))),"") | G13: =IFERROR(INDEX('macs_ips'!$G$2:$G$403,AGGREGATE(15,6,(ROW('macs_ips'!$A$2:$A$403)-ROW(INDEX('macs_ips'!$A$2:$A$403,1,1))+1)/('macs_ips'!$E$2:$E$403=$J$1),ROW(A11))),"")
A14: =IFERROR(INDEX('macs_ips'!$A$2:$A$403,AGGREGATE(15,6,(ROW('macs_ips'!$A$2:$A$403)-ROW(INDEX('macs_ips'!$A$2:$A$403,1,1))+1)/('macs_ips'!$E$2:$E$403=$J$1),ROW(A12))),"") | B14: =IFERROR(INDEX('macs_ips'!$B$2:$B$403,AGGREGATE(15,6,(ROW('macs_ips'!$A$2:$A$403)-ROW(INDEX('macs_ips'!$A$2:$A$403,1,1))+1)/('macs_ips'!$E$2:$E$403=$J$1),ROW(A12))),"") | C14: =IFERROR(INDEX('macs_ips'!$C$2:$C$403,AGGREGATE(15,6,(ROW('macs_ips'!$A$2:$A$403)-ROW(INDEX('macs_ips'!$A$2:$A$403,1,1))+1)/('macs_ips'!$E$2:$E$403=$J$1),ROW(A12))),"") | D14: =IFERROR(INDEX('macs_ips'!$D$2:$D$403,AGGREGATE(15,6,(ROW('macs_ips'!$A$2:$A$403)-ROW(INDEX('macs_ips'!$A$2:$A$403,1,1))+1)/('macs_ips'!$E$2:$E$403=$J$1),ROW(A12))),"") | E14: =IFERROR(INDEX('macs_ips'!$E$2:$E$403,AGGREGATE(15,6,(ROW('macs_ips'!$A$2:$A$403)-ROW(INDEX('macs_ips'!$A$2:$A$403,1,1))+1)/('macs_ips'!$E$2:$E$403=$J$1),ROW(A12))),"") | F14: =IFERROR(INDEX('macs_ips'!$F$2:$F$403,AGGREGATE(15,6,(ROW('macs_ips'!$A$2:$A$403)-ROW(INDEX('macs_ips'!$A$2:$A$403,1,1))+1)/('macs_ips'!$E$2:$E$403=$J$1),ROW(A12))),"") | G14: =IFERROR(INDEX('macs_ips'!$G$2:$G$403,AGGREGATE(15,6,(ROW('macs_ips'!$A$2:$A$403)-ROW(INDEX('macs_ips'!$A$2:$A$403,1,1))+1)/('macs_ips'!$E$2:$E$403=$J$1),ROW(A12))),"")
... A452: =IFERROR(INDEX('macs_ips'!$A$2:$A$403,AGGREGATE(15,6,(ROW('macs_ips'!$A$2:$A$403)-ROW(INDEX('macs_ips'!$A$2:$A$403,1,1))+1)/('macs_ips'!$E$2:$E$403=$J$1),ROW(A450))),"") | B452: =IFERROR(INDEX('macs_ips'!$B$2:$B$403,AGGREGATE(15,6,(ROW('macs_ips'!$A$2:$A$403)-ROW(INDEX('macs_ips'!$A$2:$A$403,1,1))+1)/('macs_ips'!$E$2:$E$403=$J$1),ROW(A450))),"") | C452: =IFERROR(INDEX('macs_ips'!$C$2:$C$403,AGGREGATE(15,6,(ROW('macs_ips'!$A$2:$A$403)-ROW(INDEX('macs_ips'!$A$2:$A$403,1,1))+1)/('macs_ips'!$E$2:$E$403=$J$1),ROW(A450))),"") | D452: =IFERROR(INDEX('macs_ips'!$D$2:$D$403,AGGREGATE(15,6,(ROW('macs_ips'!$A$2:$A$403)-ROW(INDEX('macs_ips'!$A$2:$A$403,1,1))+1)/('macs_ips'!$E$2:$E$403=$J$1),ROW(A450))),"") | E452: =IFERROR(INDEX('macs_ips'!$E$2:$E$403,AGGREGATE(15,6,(ROW('macs_ips'!$A$2:$A$403)-ROW(INDEX('macs_ips'!$A$2:$A$403,1,1))+1)/('macs_ips'!$E$2:$E$403=$J$1),ROW(A450))),"") | F452: =IFERROR(INDEX('macs_ips'!$F$2:$F$403,AGGREGATE(15,6,(ROW('macs_ips'!$A$2:$A$403)-ROW(INDEX('macs_ips'!$A$2:$A$403,1,1))+1)/('macs_ips'!$E$2:$E$403=$J$1),ROW(A450))),"") | G452: =IFERROR(INDEX('macs_ips'!$G$2:$G$403,AGGREGATE(15,6,(ROW('macs_ips'!$A$2:$A$403)-ROW(INDEX('macs_ips'!$A$2:$A$403,1,1))+1)/('macs_ips'!$E$2:$E$403=$J$1),ROW(A450))),"")

Sheet SEM_RESPOSTA
A1: CLIENTES — Sem resposta | J1: Sem resposta
A2: MAC | B2: Ips | C2: Contactos | D2: data exp | E2: Situação | F2: data da proxima ação | G2: observação
A3: =IFERROR(INDEX('macs_ips'!$A$2:$A$403,AGGREGATE(15,6,(ROW('macs_ips'!$A$2:$A$403)-ROW(INDEX('macs_ips'!$A$2:$A$403,1,1))+1)/('macs_ips'!$E$2:$E$403=$J$1),ROW(A1))),"") | B3: =IFERROR(INDEX('macs_ips'!$B$2:$B$403,AGGREGATE(15,6,(ROW('macs_ips'!$A$2:$A$403)-ROW(INDEX('macs_ips'!$A$2:$A$403,1,1))+1)/('macs_ips'!$E$2:$E$403=$J$1),ROW(A1))),"") | C3: =IFERROR(INDEX('macs_ips'!$C$2:$C$403,AGGREGATE(15,6,(ROW('macs_ips'!$A$2:$A$403)-ROW(INDEX('macs_ips'!$A$2:$A$403,1,1))+1)/('macs_ips'!$E$2:$E$403=$J$1),ROW(A1))),"") | D3: =IFERROR(INDEX('macs_ips'!$D$2:$D$403,AGGREGATE(15,6,(ROW('macs_ips'!$A$2:$A$403)-ROW(INDEX('macs_ips'!$A$2:$A$403,1,1))+1)/('macs_ips'!$E$2:$E$403=$J$1),ROW(A1))),"") | E3: =IFERROR(INDEX('macs_ips'!$E$2:$E$403,AGGREGATE(15,6,(ROW('macs_ips'!$A$2:$A$403)-ROW(INDEX('macs_ips'!$A$2:$A$403,1,1))+1)/('macs_ips'!$E$2:$E$403=$J$1),ROW(A1))),"") | F3: =IFERROR(INDEX('macs_ips'!$F$2:$F$403,AGGREGATE(15,6,(ROW('macs_ips'!$A$2:$A$403)-ROW(INDEX('macs_ips'!$A$2:$A$403,1,1))+1)/('macs_ips'!$E$2:$E$403=$J$1),ROW(A1))),"") | G3: =IFERROR(INDEX('macs_ips'!$G$2:$G$403,AGGREGATE(15,6,(ROW('macs_ips'!$A$2:$A$403)-ROW(INDEX('macs_ips'!$A$2:$A$403,1,1))+1)/('macs_ips'!$E$2:$E$403=$J$1),ROW(A1))),"")
A4: =IFERROR(INDEX('macs_ips'!$A$2:$A$403,AGGREGATE(15,6,(ROW('macs_ips'!$A$2:$A$403)-ROW(INDEX('macs_ips'!$A$2:$A$403,1,1))+1)/('macs_ips'!$E$2:$E$403=$J$1),ROW(A2))),"") | B4: =IFERROR(INDEX('macs_ips'!$B$2:$B$403,AGGREGATE(15,6,(ROW('macs_ips'!$A$2:$A$403)-ROW(INDEX('macs_ips'!$A$2:$A$403,1,1))+1)/('macs_ips'!$E$2:$E$403=$J$1),ROW(A2))),"") | C4: =IFERROR(INDEX('macs_ips'!$C$2:$C$403,AGGREGATE(15,6,(ROW('macs_ips'!$A$2:$A$403)-ROW(INDEX('macs_ips'!$A$2:$A$403,1,1))+1)/('macs_ips'!$E$2:$E$403=$J$1),ROW(A2))),"") | D4: =IFERROR(INDEX('macs_ips'!$D$2:$D$403,AGGREGATE(15,6,(ROW('macs_ips'!$A$2:$A$403)-ROW(INDEX('macs_ips'!$A$2:$A$403,1,1))+1)/('macs_ips'!$E$2:$E$403=$J$1),ROW(A2))),"") | E4: =IFERROR(INDEX('macs_ips'!$E$2:$E$403,AGGREGATE(15,6,(ROW('macs_ips'!$A$2:$A$403)-ROW(INDEX('macs_ips'!$A$2:$A$403,1,1))+1)/('macs_ips'!$E$2:$E$403=$J$1),ROW(A2))),"") | F4: =IFERROR(INDEX('macs_ips'!$F$2:$F$403,AGGREGATE(15,6,(ROW('macs_ips'!$A$2:$A$403)-ROW(INDEX('macs_ips'!$A$2:$A$403,1,1))+1)/('macs_ips'!$E$2:$E$403=$J$1),ROW(A2))),"") | G4: =IFERROR(INDEX('macs_ips'!$G$2:$G$403,AGGREGATE(15,6,(ROW('macs_ips'!$A$2:$A$403)-ROW(INDEX('macs_ips'!$A$2:$A$403,1,1))+1)/('macs_ips'!$E$2:$E$403=$J$1),ROW(A2))),"")
A5: =IFERROR(INDEX('macs_ips'!$A$2:$A$403,AGGREGATE(15,6,(ROW('macs_ips'!$A$2:$A$403)-ROW(INDEX('macs_ips'!$A$2:$A$403,1,1))+1)/('macs_ips'!$E$2:$E$403=$J$1),ROW(A3))),"") | B5: =IFERROR(INDEX('macs_ips'!$B$2:$B$403,AGGREGATE(15,6,(ROW('macs_ips'!$A$2:$A$403)-ROW(INDEX('macs_ips'!$A$2:$A$403,1,1))+1)/('macs_ips'!$E$2:$E$403=$J$1),ROW(A3))),"") | C5: =IFERROR(INDEX('macs_ips'!$C$2:$C$403,AGGREGATE(15,6,(ROW('macs_ips'!$A$2:$A$403)-ROW(INDEX('macs_ips'!$A$2:$A$403,1,1))+1)/('macs_ips'!$E$2:$E$403=$J$1),ROW(A3))),"") | D5: =IFERROR(INDEX('macs_ips'!$D$2:$D$403,AGGREGATE(15,6,(ROW('macs_ips'!$A$2:$A$403)-ROW(INDEX('macs_ips'!$A$2:$A$403,1,1))+1)/('macs_ips'!$E$2:$E$403=$J$1),ROW(A3))),"") | E5: =IFERROR(INDEX('macs_ips'!$E$2:$E$403,AGGREGATE(15,6,(ROW('macs_ips'!$A$2:$A$403)-ROW(INDEX('macs_ips'!$A$2:$A$403,1,1))+1)/('macs_ips'!$E$2:$E$403=$J$1),ROW(A3))),"") | F5: =IFERROR(INDEX('macs_ips'!$F$2:$F$403,AGGREGATE(15,6,(ROW('macs_ips'!$A$2:$A$403)-ROW(INDEX('macs_ips'!$A$2:$A$403,1,1))+1)/('macs_ips'!$E$2:$E$403=$J$1),ROW(A3))),"") | G5: =IFERROR(INDEX('macs_ips'!$G$2:$G$403,AGGREGATE(15,6,(ROW('macs_ips'!$A$2:$A$403)-ROW(INDEX('macs_ips'!$A$2:$A$403,1,1))+1)/('macs_ips'!$E$2:$E$403=$J$1),ROW(A3))),"")
A6: =IFERROR(INDEX('macs_ips'!$A$2:$A$403,AGGREGATE(15,6,(ROW('macs_ips'!$A$2:$A$403)-ROW(INDEX('macs_ips'!$A$2:$A$403,1,1))+1)/('macs_ips'!$E$2:$E$403=$J$1),ROW(A4))),"") | B6: =IFERROR(INDEX('macs_ips'!$B$2:$B$403,AGGREGATE(15,6,(ROW('macs_ips'!$A$2:$A$403)-ROW(INDEX('macs_ips'!$A$2:$A$403,1,1))+1)/('macs_ips'!$E$2:$E$403=$J$1),ROW(A4))),"") | C6: =IFERROR(INDEX('macs_ips'!$C$2:$C$403,AGGREGATE(15,6,(ROW('macs_ips'!$A$2:$A$403)-ROW(INDEX('macs_ips'!$A$2:$A$403,1,1))+1)/('macs_ips'!$E$2:$E$403=$J$1),ROW(A4))),"") | D6: =IFERROR(INDEX('macs_ips'!$D$2:$D$403,AGGREGATE(15,6,(ROW('macs_ips'!$A$2:$A$403)-ROW(INDEX('macs_ips'!$A$2:$A$403,1,1))+1)/('macs_ips'!$E$2:$E$403=$J$1),ROW(A4))),"") | E6: =IFERROR(INDEX('macs_ips'!$E$2:$E$403,AGGREGATE(15,6,(ROW('macs_ips'!$A$2:$A$403)-ROW(INDEX('macs_ips'!$A$2:$A$403,1,1))+1)/('macs_ips'!$E$2:$E$403=$J$1),ROW(A4))),"") | F6: =IFERROR(INDEX('macs_ips'!$F$2:$F$403,AGGREGATE(15,6,(ROW('macs_ips'!$A$2:$A$403)-ROW(INDEX('macs_ips'!$A$2:$A$403,1,1))+1)/('macs_ips'!$E$2:$E$403=$J$1),ROW(A4))),"") | G6: =IFERROR(INDEX('macs_ips'!$G$2:$G$403,AGGREGATE(15,6,(ROW('macs_ips'!$A$2:$A$403)-ROW(INDEX('macs_ips'!$A$2:$A$403,1,1))+1)/('macs_ips'!$E$2:$E$403=$J$1),ROW(A4))),"")
A7: =IFERROR(INDEX('macs_ips'!$A$2:$A$403,AGGREGATE(15,6,(ROW('macs_ips'!$A$2:$A$403)-ROW(INDEX('macs_ips'!$A$2:$A$403,1,1))+1)/('macs_ips'!$E$2:$E$403=$J$1),ROW(A5))),"") | B7: =IFERROR(INDEX('macs_ips'!$B$2:$B$403,AGGREGATE(15,6,(ROW('macs_ips'!$A$2:$A$403)-ROW(INDEX('macs_ips'!$A$2:$A$403,1,1))+1)/('macs_ips'!$E$2:$E$403=$J$1),ROW(A5))),"") | C7: =IFERROR(INDEX('macs_ips'!$C$2:$C$403,AGGREGATE(15,6,(ROW('macs_ips'!$A$2:$A$403)-ROW(INDEX('macs_ips'!$A$2:$A$403,1,1))+1)/('macs_ips'!$E$2:$E$403=$J$1),ROW(A5))),"") | D7: =IFERROR(INDEX('macs_ips'!$D$2:$D$403,AGGREGATE(15,6,(ROW('macs_ips'!$A$2:$A$403)-ROW(INDEX('macs_ips'!$A$2:$A$403,1,1))+1)/('macs_ips'!$E$2:$E$403=$J$1),ROW(A5))),"") | E7: =IFERROR(INDEX('macs_ips'!$E$2:$E$403,AGGREGATE(15,6,(ROW('macs_ips'!$A$2:$A$403)-ROW(INDEX('macs_ips'!$A$2:$A$403,1,1))+1)/('macs_ips'!$E$2:$E$403=$J$1),ROW(A5))),"") | F7: =IFERROR(INDEX('macs_ips'!$F$2:$F$403,AGGREGATE(15,6,(ROW('macs_ips'!$A$2:$A$403)-ROW(INDEX('macs_ips'!$A$2:$A$403,1,1))+1)/('macs_ips'!$E$2:$E$403=$J$1),ROW(A5))),"") | G7: =IFERROR(INDEX('macs_ips'!$G$2:$G$403,AGGREGATE(15,6,(ROW('macs_ips'!$A$2:$A$403)-ROW(INDEX('macs_ips'!$A$2:$A$403,1,1))+1)/('macs_ips'!$E$2:$E$403=$J$1),ROW(A5))),"")
